Workbook
Name Drop_down2: '8. Analyse'!#REF!
Name Drop_down2: '8. Analyse'!#REF!
Name Hazards: '3. Dangers'!$AA$2:$AA$5

Sheet COMMENCEZ ICI
A1: Évaluation des Vulnérabilités et des Capacités Améliorée (EVCa) | Synthèse
C6: À propos de ce modèle
C8: Ce modèle a été préparé dans l’objectif de documenter les principaux résultats d'une Évaluation des Vulnérabilités et des Capacités Améliorée (EVCa). Le principal avantage par rapport aux rapports réguliers basés sur Microsoft Word est triple. Premièrement, il calcule automatiquement le risque, sur la base de vos évaluations de l'exposition, des vulnérabilités et des capacités pour un maximum de quatre dangers. Les résultats détaillés sont présentés dans la feuille 8 (Risque), tandis que le résumé est visualisé dans un schéma EVCa en toile d'araignée dans la feuille 1. Deuxièmement, il calcule également le degré de résilience (se référer à la feuille 12 pour les résultats détaillés et le tableau récapitulatif de la feuille 1). Ainsi, les utilisateurs ayant déjà réalisé une EVCa n'ont pas besoin d'effectuer une mesure complète de la résilience. Troisièmement, ce fichier se situe dans le contexte du prochain tableau de bord de résilience, un site Internet en cours de développement. L’ensemble des résultats saisis ici seront directement lisibles par le tableau de bord, et pourront être enregistrés sous votre compte utilisateur. Vous pourrez réappliquer régulièrement la mesure de base, et de ce fait comparer les résultats EVCa « de base » avec ceux de l'évaluation finale » si vous le souhaitez. | K8: Utilisez le guide EVCa pour une orientation générale. Préparez ce modèle lorsque vous menez une EVCa. Toutes les informations peuvent être saisies hors ligne - ultérieurement (lorsque le tableau de bord de résilience est en ligne), vous pouvez télécharger le fichier complété. Notez que vous ne pouvez saisir que les cellules dotées d’un cadre rouge. Dans la mesure où le fichier contient de nombreuses formules, il est protégé par un mot de passe - et ce afin d'éviter d'endommager accidentellement ces formules. Si vous devez déverrouiller le fichier (par exemple pour traduire le texte), allez dans OUTILS --> PROTECTION --> ÔTER LA PROTECTION --> SAISIR LE MOT DE PASSE : eVCA. Veuillez ne pas modifier la structure (c'est-à-dire ajouter ou supprimer des cellules). Veuillez également noter que certaines cellules contiennent des listes déroulantes, à partir desquelles vous pouvez effectuer une sélection. Pour toute question, veuillez contacter Stéphanie Julmy à l'adresse stephanie.julmy@ifrc.org.

Sheet 1. Résumé
A1: Évaluation des Vulnérabilités et des Capacités Améliorée (EVCa) | Synthèse
A3: Aperçu
A5: Informations générales
E6: FKT 09/12 Manometinay | G6: Quartiers : Fkt 09/12 Manometinay
E8: Province / État : Toliara | G8: Pays : Madagascar
E10: Société nationale : Croix-Rouge Malagasy | G10: Branche : Morondava
E12: Date de début de l’EVCa : 09/06/2025 | G12: Contact : 0348736810
E14: Date de fin de l’EVCa : 13/06/2025 | G14: Position : Président de District
E16: Coordonnées GPS de la communauté | G16: Courriel
A19: 1.a Résumé analytique
C21: Incluez la manière et le processus avec lesquels la communauté a été sélectionnée.
C22: L'EVCa consiste en un processus participatif d'évaluation des risques communautaires développé afin que les communautés acquièrent davantage de résilience à travers l'évaluation et l'analyse des dangers qui les menacent et l'identification de solutions.
C24: Dans le cadre du projet Programme local de Préparation et de Résilience aux aléas Multiples (PPRM) financé par la FCDO mis en oeuvre par la Croix-Rouge Malagasy , des activités de préparation et anticipation ont identifiés comme besoin crucial pour préparer cette saison cyclonique 2025– 2026. Ainsi, la région Menabe a été identifiée comme zone favorable pour mener une Evaluation des Vulnérabilités et Capacités améliorée (EVCA). Un atelier EVCA est ainsi organisé dans 01 fokontany de la ville de Morondava et 05 fokontany pour la commune de Belo sur mer. La méthodologie adoptée pour l'identification des représentants des communautés sélectionnées à été la suivante : approche participative avec implication et responsabilisation de la communauté qui se voit chargée de désigner les représentants des différentes entités présentes dans les Fokontany afin que ces derniers participent à l'atelier. Cette phase s'est déroulée sur trois jours par Fokontany et doit faire émerger les 20 représentants de la communauté présents à l'EVCA en incluant les secteurs pouvant être affectés par le passage d'un aléas, à savoir : l’éducation, la santé, eau et assainissement, le logement, la nourriture et la sécurité alimentaire, les infrastructures et services, la gestion des ressources naturelles, et la sécurité. L'identification de ces représentants s'est faite lors d'une réunion communautaire. Les participants identifiés ont été les suivants : - Représentant du FKT (President etVice president Fokontany) en tant qu’observateurs - Représentant de la CRM Districal - Représentant des personnes âgées - Représentant des Jeunes - Représentant des Femmes - Représentant de la société civile - Représentant du secteur éducation - Représentant des commerçants - Représentant des éleveurs - Représentant des cultivateurs et pecheurs - Agent communautaire
K35: Valeurs clés (non imprimées). Référez-vous à la feuille 8 pour les risques et à la feuille 12 pour la résilience.
A36: 1.b Modèle de risque | L36: Danger 1
C39: SECHERESSE
C40: Ampleur | E40: Cote de risque
C41: 1. Gestion des Risques de Catastrophe | E41: FAIBLE
C42: 2. Santé | E42: MOYENNE
C43: 3. Eau et assainissement | E43: ELEVEE
C44: 4. Logement | E44: FAIBLE
C45: 5. Alimentation et nutrition | E45: ELEVEE
C46: 6. Cohésion sociale | E46: FAIBLE
C47: 7. Inclusion | E47: ELEVEE
C48: 8. Opportunités économiques | E48: ELEVEE
C49: 9. Infrastructure et services | E49: FAIBLE
C50: 10. Gestion des ressources naturelles | E50: MOYENNE
C51: 11. Connectivité | E51: MOYENNE
C53: Innondation
C54: Ampleur | E54: Cote de risque
C55: 1. Gestion des Risques de Catastrophe | E55: MOYENNE
C56: 2. Santé | E56: ELEVEE
C57: 3. Eau et assainissement | E57: ELEVEE
C58: 4. Logement | E58: ELEVEE
C59: 5. Alimentation et nutrition | E59: ELEVEE
C60: 6. Cohésion sociale | E60: FAIBLE
C61: 7. Inclusion | E61: ='[1]7. Risque'!$M$39 -> MOYENNE
C62: 8. Opportunités économiques | E62: ELEVEE
C63: 9. Infrastructure et services | E63: ELEVEE
C64: 10. Gestion des ressources naturelles | E64: ELEVEE
...

Sheet 2. Contexte
A1: Évaluation des Vulnérabilités et des Capacités Améliorée (EVCa) | Synthèse
A3: Informations contextuelles
A5: Informations générales
E6: ='1. Résumé'!E6 -> FKT 09/12 Manometinay | K6: Madagascar | R6: Croix-Rouge Malagasy
A9: 3. Description et contexte de la communauté
C11: Fournissez un bref aperçu de la communauté.
C13: La région Menabe est l'une des vingt-trois régions de Madagascar. Elle est située dans la province de Toliara, dans la côte-ouest de l'île.Morondava, chef-lieu de la région Menabe et concentre 6,6% de sa population urbaine. Elle se situe dans la région Menabe, sur la côte ouest du pays, au débouché de l'ocean indien, axe majeur de transport de marchandises, à environ 697 kilomètres d’Antananarivo via la route nationale 7 et 35. Morondava est composée 4 commune rural et de 18 fokontany et rassemble 22% de la population de la région menabe, avec 178 966 habitants pour une superficie de 28km22, soit une densité moyenne de 10 534 habitants/km2. Principal port du pays et parmi les plus importants de l’océan Indien, la ville est un lieu de transit de marchandises et de tourisme et son économie est majoritairement basée sur la pêche ainsi que sur l’agriculture, rendant les populations fortement dépendantes des ressources naturelles dont elles disposent. La ville de Morondava est caractérisée par un climat tropical chaud et humide avec une saison chaude et pluvieuse entre novembre et avril. La ville de Morondava est particulièrement vulnérable aux cyclones en raison de sa position géographique et de son élévation basse. Les sols, sablonneux et argileux, ne sont que très peu perméables, générant des problèmes d’évacuation des eaux. La ville, de par sa position géographique et sa densité de population, est particulièrement vulnérable aux aléas climatiques. Ces derniers ont d’importants impacts sur les lieux d’implantation humaine mais également sur les sites de production économique ou de culture, exposant les communautés à des risques d’insécurité alimentaire. Les habitants disposent généralement d’une capacité d’adaptation limitée en raison du niveau de pauvreté et du manque d’infrastructures. La ville de Morondava ne compte par exemple que deux centres de santé de base et un centres hospitaliers universitaires pour une population de près de 178 966 habitants. Entre 1982 et 2018, la région Menabe a été touchée par 32 cyclones, dont plusieurs ont été qualifiés de cyclones tropicaux en raison de leur intensité. Morondava se trouve ainsi être la ville la plus exposée au risque de pertes directes dues aux cyclones tropicaux, avec des pertes annuelles moyennes estimées à 20 millions de dollars. En plus d’affecter les populations, leurs habitations et moyens de subsistance, les cyclones peuvent perturber les importations, notamment de combustibles fossiles, limitant temporairement la production thermique à l’échelle nationale. Les inondations sont également très fréquentes dans la ville de Morondava et impactent principalement les habitations. L’immense majorité des pertes directes dues aux cyclones et inondations concernent le secteur résidentiel - respectivement 53 et 66%. Ces phénomènes peuvent également avoir des conséquences sur la santé des populations, exposant les communautés à de nombreux risques de maladies gastro-intestinales liées aux eaux stagnantes ou à la contamination des eaux de boisson. En outre, la zone est sujette à l’érosion marine et terrestre, dont l’accélération progressive a généré l’ensablement de la rade du port. Ces phénomènes météorologiques extrêmes, leur intensité, récurrence et effets néfastes se trouvent exacerbés par le réchauffement climatique. Morondava est aujourd’hui confrontée à une hausse de ses températures, à une élévation du niveau de la mer et à une perturbation du régime pluviométrique. Le modèle climatique médian prévoit par exemple une élévation du niveau de la mer de 11 centimètres d’ici 2030 et de 43 centimètres d’ici 2080 pour les côtes malgaches. Ce phénomène pourrait générer une intrusion saline dans les terres, les eaux souterraines et les zones humides littorales, ce qui représente une menace élevée pour les communautés côtières de la ville, leurs activités agricoles et leur approvisionnement en eau potable mais également pour les écosystèmes. Ainsi, tous ces risques hydro climatiques et environnementaux ont des répercussions majeures sur les populations et leurs moyens de subsistance, leur habitat et les besoins relatifs à l’eau, l’assainissement et à la santé. De manière plus spécifique, le Fokontany Manometinay 07/12 (6 campements et 12 secteurs) est composé de la sorte Secteur 1 : population de habitants ( hommes et femmes) répartis en ménages avec une moyenne de personnes par ménage Secteur 2 : population de habitants ( hommes et femmes) répartis en ménages avec une moyenne de personnes par ménage Le fokontany 08/12 Manometinay regroupe ainsi 10303 habitants dont hommes et femmes Les principaux risques auxquels fait face la communauté sont les suivants : sécheresse , Cyclone, Innondation et épidemie avec le défécation à l'air libre et la mauvaise gestion des déchets ce qui génère des maladies. Le fokontany a été touché par le Choléra depuis l'année 2000 et la sècheresse pendant 6 ans (2016 - 2022)
C15: 3a Population
C17: Répartition par sexe et tranche d'âge | E17: 0 - 5 ans | I17: 6 - 17 ans | M17: 18 - 65 ans | Q17: 66 ans et plus | U17: Total
E18: Hommes | F18: Femmes | G18: Sous-total | I18: Hommes | J18: Femmes | K18: Sous-total | M18: Hommes | N18: Femmes | O18: Sous-total | Q18: Hommes | R18: Femmes | S18: Sous-total | U18: Hommes | V18: Femmes | W18: Global
C20: Nombre de personnes Saisissez les données dans les cellules encadrées de rouge | K20: =SUM(I20:J20) -> 0 | M20: 9 | N20: 9 | O20: =SUM(M20:N20) -> 18 | Q20: 1 | R20: 0 | S20: =SUM(Q20:R20) -> 1 | U20: =M20+Q20 -> 10 | V20: =N20+R20 -> 9 | W20: 780
C22: Part des sexes par tranche d'âge (automatique) | E22: =E20/G20 -> #DIV/0! | F22: =F20/G20 -> #DIV/0! | G22: =SUM(E22:F22) -> #DIV/0! | I22: =I20/K20 -> #DIV/0! | J22: =J20/K20 -> #DIV/0! | K22: =SUM(I22:J22) -> #DIV/0! | M22: =M20/O20 -> 0.5 | N22: =N20/O20 -> 0.5 | O22: =SUM(M22:N22) -> 1 | Q22: =Q20/S20 -> 1 | R22: =R20/S20 -> 0 | S22: =SUM(Q22:R22) -> 1 | U22: =U20/W20 -> 0.012820513 | V22: =V20/W20 -> 0.011538462 | W22: =SUM(U22:V22) -> 0.024358974
C24: Nombre de personnes handicapées (estimation si les données ne sont pas disponibles) | F24: 0 | G24: =SUM(E24:F24) -> 0 | J24: 0 | K24: =SUM(I24:J24) -> 0 | O24: =SUM(M24:N24) -> 0 | Q24: 0 | R24: 0 | S24: =SUM(Q24:R24) -> 0 | W24: 25
C26: Combien de personnes (approximativement) ont contribué à cette EVCa ? | U26: =U20+U24 -> 10 | V26: =V20+V24 -> 9 | W26: =SUM(U26:V26) -> 19
U27: =U26/U20 -> 1 | V27: =V26/V20 -> 1 | W27: =W26/W20 -> 0.024358974
C29: 3b Type de contexte Cette communauté se trouve-t-elle en milieu urbain, rural ou mixte ? | E29: Rural | I29: 3c Environnement géophysique. Effectuez des sélections afin de décrire le cadre géophysique. | M29: Côtier | Q29: 3D Activités de subsistance Quelles sont les deux principales activités de subsistance dans cette communauté ? (Sélectionnez dans la liste) | U29: Pêche, pisciculture, collecte de produits aquatiques
M31: Terrain principalement plat | U31: Pêche, pisciculture, collecte de produits aquatiques
C33: Commentaires additionnels sur le type de contexte | E33: souvent touché par l'Innondation, Sècheresse, l'épidemie ainsi que la cyclone | I33: Commentaires additionnels sur l’environnement géophysique | M33: Fokontany situé en zone enclavé de la ville | Q33: Ajoutez d'autres activités de subsistance ici. | U33: Peche et collecte des produits locaux
A38: 3. Processus d’évaluation
C40: Décrivez le processus d’évaluation. (Période ? Personnes impliquées ? Parties prenantes impliquées ? Données secondaires et outils utilisés ?
C42: Les zones ont été choisi selon les résultats d'Enquetes et les critères de vulnérabilité que le projet a réalisée. Une fois les Fokontany identifiés, on a procédé à l'identification des personnes qui vont participer à l'atelier. pour cela, les critère sont comme suit: - Représentant du FKT (Chef Fokontany, chefs des hameaux) - Représentant des chretiens - Représentant de la CRM Regional - Représentant des personnes âgées - Représentant des Jeunes - Représentant des Femmes - Représentant des commerçants - Représentant du secteur éducation - Représentant du pecheur - Agent communautaire Durant le processus, les autorités locales (Préfecture, Commune, Arrondissement) ainsi que le BNGRC, le MEN ainsi que les gouvernences locales ont été toujours impliqués.
C46: Liste déroulante 2b | E46: Liste déroulante 2d
C47: Urbain | E47: Production végétale et maraîchère
C48: Rural | E48: Production animale
C49: Mixte | E49: Pêche, pisciculture, collecte de produits aquatiques
C51: Liste déroulante 2c1 | E51: Fabrication
C52: Côtier | E52: Services
C53: Continental, avec d'importants fleuves | E53: Commerce
C54: Continental, dépourvu de fleuves importants
C56: Liste déroulante 2c2
C57: Terrain principalement plat
C58: Terrain principalement montagneux

Sheet 3. Dangers
A1: Évaluation des Vulnérabilités et des Capacités Améliorée (EVCa) | Synthèse | AA1: Dangers
AA2: =IF(E18="","",E18) -> Sècheresse
AA3: =IF(O18="","",O18) -> Innondation
A4: Informations générales | AA4: =IF(E34="","",E34) -> Epidémies
E5: ='1. Résumé'!E6 -> FKT 09/12 Manometinay | K5: ='1. Résumé'!G8 -> Pays : Madagascar | R5: ='1. Résumé'!E10 -> Société nationale : Croix-Rouge Malagasy | AA5: =IF(O34="","",O34) -> Cyclone
A8: 4. Dangers prioritaires
C10: Dans cette section, dressez la liste des dangers par ordre de priorité (en fonction de l'impact et de la fréquence passés et/ou des risques futurs) et de leurs caractéristiques. Référez-vous aux directives EVCa à la page 34
C12: Décrivez brièvement la base sur laquelle les dangers prioritaires ont été identifiés.
C14: Les dangers identifiés comme prioritaires sont les suivants : Sècheresse ; Innondation ; épidémie . Les aléas ont été identifiés grace aux outils : profil historique, calendrier saisonnier, matrice des risques, cartographie, marche transversale
C16: Sècheresse | M16: Innondation
C18: Nom/type de danger | E18: Sècheresse | M18: Nom/type de danger | O18: Innondation
C20: Cause/origine : | E20: insuffisance de la pluie | M20: Cause/origine : | O20: Changement climatique, perturbation ou dépression tropicale ,catastrophe naturelle
C22: Signes précurseurs : | E22: La montée des "Gagalato" sur le rivage sèche, les Railovy pondent ses œufs sur le sol mais plus sur l'arbre | M22: Signes précurseurs : | O22: Les "Folakobo" remontent sur la terre sèche, Pluie intense
C24: Délai : | E24: Non défini | M24: Délai : | O24: non défini
C26: Fréquence : | E26: très fort | M26: Fréquence : | O26: Moyenne
C28: Période d’occurrence : | E28: Octobre - Décembre | M28: Période d’occurrence : | O28: Janvier - fevrier
C30: Durée : | E30: 2 mois | M30: Durée : | O30: 1 Jours
C32: Epidémies | M32: Cyclone
C34: Nom/type de danger | E34: Epidémies | M34: Nom/type de danger | O34: Cyclone
C36: Cause/origine : | E36: Pollution de l'eau, invasion des moustiques, saleté, augmentation de la temperature, eau staignante, contamination des aliments | M36: Cause/origine : | O36: Changement climatique, perturbation ou dépression tropicale ,catastrophe naturelle
C38: Signes précurseurs : | E38: refroidissement, maux de tete, vomissement, apparition bes boutons, augmentation de temperature, mal digestion, | M38: Signes précurseurs : | O38: Information médiatique
C40: Délai : | E40: Non définie | M40: Délai : | O40: 5 jours
C42: Fréquence : | E42: très fort | M42: Fréquence : | O42: Fort
C44: Période d’occurrence : | E44: Janvier au Novembre | M44: Période d’occurrence : | O44: Janvier - Mars
C46: Durée : | E46: ça dépant | M46: Durée : | O46: 1 Jours
C48: Combien de dangers prioritaires avez-vous inclus ci-dessus (minimum 1, maximum 3) ? | V48: 3

Sheet 4. Vulnérabilité
A1: Évaluation des Vulnérabilités et des Capacités Améliorée (EVCa) | Synthèse
A4: Informations générales
E5: ='1. Résumé'!E6 -> FKT 09/12 Manometinay | K5: ='1. Résumé'!G8 -> Pays : Madagascar | R5: ='1. Résumé'!E10 -> Société nationale : Croix-Rouge Malagasy
A8: 6. Vulnérabilité
C10: Si nécessaire, ajoutez une brève analyse globale de la vulnérabilité ci-dessous.
C12: Il y avait des représentants des femmes, des représentants des jeunes , des sociétés civiles. Ces derniers nous ont expliqué qu'il n'y avait pas de vulnérabilité particulière pour ces groupes car toute la communauté est affectée et se débrouille eux meme .
A14: ] | C14: Qu'est-ce qui rend la communauté, ou des groupes particuliers au sein de la communauté, vulnérables ? Identifiez les groupes vulnérables au sein de votre communauté. | M14: Qu’est-ce qui les rend vulnérables ? Énumérez les vulnérabilités particulières pour chacun des groupes.
C16: Groupe vulnérable 1 | E16: Les personnes à faibles revenus ont moins de moyens pour se protéger, se préparer ou se rétablir face à une crise (accès limité à des logements solides, aux soins médicaux ou à des assurances). | M16: Groupe vulnérable 1 | O16: Des facteurs liés à des aspects sociaux
C18: Groupe vulnérable 2 | E18: Les familles dépendant d’une seule ressource (comme l’agriculture ou la pêche) sont plus vulnérables aux perturbations causées par les catastrophes naturelles ou économiques. Une dépendance excessive à des activités affectées par les événements climatiques (comme l’agriculture de subsistance) accroît la vulnérabilité. | M18: Groupe vulnérable 2 | O18: Des facteurs économiques : Dépendance à une économie fragile :
C20: Groupe vulnérable 3 | E20: n/a | M20: Groupe vulnérable 3 | O20: n/a
C22: Groupe vulnérable 4 | E22: n/a | M22: Groupe vulnérable 4 | O22: n/a
C24: Sécheresse
C26: Énumérez et décrivez les impacts (passés et futurs), les aspects de vulnérabilité (y compris les causes profondes) et le niveau (élevé, moyen, faible) de vulnérabilité en utilisant les dimensions clés de la résilience. Référez-vous aux directives EVCa à la page 39.
C28: Ampleur | G28: Impact (passé et futur) | M28: Aspects de vulnérabilité avec leurs causes (la raison pour laquelle l'impact se produit et les causes profondes) | S28: Cote de vulnérabilité (choisissez dans la liste) | V28: Valeur de VUL
C29: 1. Gestion des Risques de Catastrophe | S29: AUCUNE vulnérabilité | V29: =IF(S29="---","",VLOOKUP(S29,$C$63:$D$66,2,FALSE)) -> #N/A
C30: 2. Santé | G30: l'aggravité de maladie et l'épidemie pourra propager | M30: Manque d'équipement des AC, les gens ne resiste pas les maladies pendant la sècheresse | S30: Vulnérabilité MOYENNE | V30: =IF(S30="---","",VLOOKUP(S30,$C$63:$D$66,2,FALSE)) -> #N/A
C31: 3. Eau et assainissement | G31: la population ne consomme pas d'eau irrégulièrement et s'affaibli | M31: eau sèche et insuffisante | S31: Vulnérabilité ELEVEE | V31: =IF(S31="---","",VLOOKUP(S31,$C$63:$D$66,2,FALSE)) -> #N/A
C32: 4.Logement | G32: > effondrement partiel ou total des structures, nécessité de réparations coûteuses. | S32: Vulnérabilité MOYENNE | V32: =IF(S32="---","",VLOOKUP(S32,$C$63:$D$66,2,FALSE)) -> #N/A
C33: 5. Alimentation et nutrition | G33: > Insufisance alimentaire ; Malnutrition , | M33: Manque d'approvisionnement alimentaire et des stocks | S33: Vulnérabilité ELEVEE | V33: =IF(S33="---","",VLOOKUP(S33,$C$63:$D$66,2,FALSE)) -> #N/A
C34: 6. Opportunités économiques | G34: >Baisse des revenus maritimes, pénuries alimentaires locales | M34: difficulté de cultivé; baisse de revenu | S34: Vulnérabilité ELEVEE | V34: =IF(S34="---","",VLOOKUP(S34,$C$63:$D$66,2,FALSE)) -> #N/A
C35: 7. Infrastructure et services | S35: Vulnérabilité MOYENNE | V35: =IF(S35="---","",VLOOKUP(S35,$C$63:$D$66,2,FALSE)) -> #N/A
C36: 8. Gestion des ressources naturelles | G36: la sècheresse causent des dégâts à la forêt du à m'augmentation de la chaleur et la manque d'eau | M36: la forêt sont vulnérable face au danger | S36: Vulnérabilité MOYENNE | V36: =IF(S36="---","",VLOOKUP(S36,$C$63:$D$66,2,FALSE)) -> #N/A
C37: 6. Social cohesion & Inclusion | G37: =#REF! -> #REF! | M37: =#REF! -> #REF! | S37: =#REF! -> #REF! | V37: =IF(S37="---","",VLOOKUP(S37,$C$63:$D$66,2,FALSE)) -> #REF!
C39: ='3. Dangers'!M16 -> Innondation
C41: Ampleur | G41: Impact (passé et futur) | M41: Aspects de vulnérabilité avec leurs causes (la raison pour laquelle l'impact se produit et les causes profondes) | S41: Cote de vulnérabilité (choisissez dans la liste) | V41: Valeur de VUL
C42: 1. Gestion des Risques de Catastrophe | G42: > Aggravation des impacts humanitaires, y compris la pénuries alimentaires, les déplacements de populations, et une détérioration des conditions de vie. > Augmentation des dégats materiaux et des biens | M42: La population ont du mal a etre bien informé en raison de l'inéxistance des ELS biens equipés et des outils SAP; ceci les rend toujours vulnérables et sans préparation à la résilience | S42: Vulnérabilité ELEVEE | V42: =IF(S42="---","",VLOOKUP(S42,$C$63:$D$66,2,FALSE)) -> #N/A
C43: 2. Santé | G43: >Propagation des maladies; le retard de la prise en charge des personnes infectés par la maladie peut causé de la perte de vie | M43: pollution et cumulation des déchets | S43: Vulnérabilité ELEVEE | V43: =IF(S43="---","",VLOOKUP(S43,$C$63:$D$66,2,FALSE)) -> #N/A
C44: 3. Eau et assainissement | G44: la population ne consomme pas d'eau régulièrement et s'affaibli | M44: > Manque d'accés à l'eau potable | S44: Vulnérabilité ELEVEE | V44: =IF(S44="---","",VLOOKUP(S44,$C$63:$D$66,2,FALSE)) -> #N/A
C45: 4.Logement | G45: > Destruction des maisons > décoifé des toitures , déracinée des arbres, prévention des sans abris | M45: La fragilité de la structure des logements rend sa destruction rapide face au danger | S45: Vulnérabilité MOYENNE | V45: =IF(S45="---","",VLOOKUP(S45,$C$63:$D$66,2,FALSE)) -> #N/A
C46: 5. Alimentation et nutrition | G46: l'intolérance alimentaire peut causer de l'Insufisance alimentaire ; Malnutrition , | M46: >intolérance alimentaire du à la saleté d'eau | S46: Vulnérabilité ELEVEE | V46: =IF(S46="---","",VLOOKUP(S46,$C$63:$D$66,2,FALSE)) -> #N/A
C47: 6. Opportunités économiques | G47: Ce vulnérabilité a pour impact la Baisse des revenus, les pénuries alimentaires | M47: > Intérruption des activités de substance | S47: Vulnérabilité ELEVEE | V47: =IF(S47="---","",VLOOKUP(S47,$C$63:$D$66,2,FALSE)) -> #N/A
C48: 7. Infrastructure et services | G48: l'isolement de la communauté et la survi de la population ne compte qu'à soi meme | M48: indisponibilité de transport et interruption de l'activité routière | S48: Vulnérabilité MOYENNE | V48: =IF(S48="---","",VLOOKUP(S48,$C$63:$D$66,2,FALSE)) -> #N/A
C49: 8. Gestion des ressources naturelles | G49: les arbres sont déracinés et pourra causer de la perte de vie des animaux | M49: la forêt sont vulnérable en vue la forte pression du danger; | S49: Vulnérabilité MOYENNE | V49: =IF(S49="---","",VLOOKUP(S49,$C$63:$D$66,2,FALSE)) -> #N/A
C51: ='3. Dangers'!C32 -> Epidémies
C53: Ampleur | G53: Impact (passé et futur) | M53: Aspects de vulnérabilité avec leurs causes (la raison pour laquelle l'impact se produit et les causes profondes) | S53: Cote de vulnérabilité (choisissez dans la liste) | V53: Valeur de VUL
C54: 1. Gestion des Risques de Catastrophe | G54: la propagation de la maladie et retard du prise en charge du malade qui pourra causer sa mortalité | M54: manque de sensibilisation, ne pas suivre les consignes du leader | S54: Vulnérabilité MOYENNE | V54: =IF(S54="---","",VLOOKUP(S54,$C$63:$D$66,2,FALSE)) -> #N/A
C55: 2. Santé | G55: la propagation de la maladie et retard du prise en charge du malade qui pourra causer sa mortalité | M55: Auto-médecine, manque de médecin | S55: Vulnérabilité MOYENNE | V55: 0.67
C56: 3. Eau et assainissement | G56: > consomation d'eau non potable > Propagation rapide de l'épidémie dans les communautés | M56: cumulation des déchets, pollution d'eau potable | S56: Vulnérabilité ELEVEE | V56: =IF(S56="---","",VLOOKUP(S56,$C$63:$D$66,2,FALSE)) -> #N/A
C57: 4.Logement | G57: >Transmission rapide des maladies infectieuses, en particulier dans les logements partagés et Sales | M57: saleté et étroite de logement | S57: Vulnérabilité MOYENNE | V57: =IF(S57="---","",VLOOKUP(S57,$C$63:$D$66,2,FALSE)) -> #N/A
C58: 5. Alimentation et nutrition | G58: > Apparition de crises alimentaires locales dues à une perturbation de la production, de la distribution ou de l'accès à la nourriture.Malnutrition , manque d'apetit | M58: >intolérance alimentaire et sale | S58: Vulnérabilité ELEVEE | V58: =IF(S58="---","",VLOOKUP(S58,$C$63:$D$66,2,FALSE)) -> #N/A
...

Sheet 5. Capacité
A1: Évaluation des Vulnérabilités et des Capacités Améliorée (EVCa) | Synthèse
A4: Informations générales
E5: ='1. Résumé'!E6 -> FKT 09/12 Manometinay | K5: ='1. Résumé'!G8 -> Pays : Madagascar
A8: 7. Capacité
C10: Quelles sont les forces disponibles pouvant être mobilisées et exploitée dans le but de réduire l'impact d'un danger ? Énumérez et décrivez les capacités (au niveau de la communauté, du ménage et de l'individu) qui existent pour faire face à chaque danger prioritaire en utilisant les caractéristiques clés de la résilience. Référez-vous aux directives EVCa à la page 40.
C12: Si nécessaire, ajoutez une brève analyse globale de la capacité ci-dessous.
C14: Pour réduire l'impact des dangers, il est crucial de mobiliser et d'exploiter les forces disponibles à différents niveaux (communautaire, économique et environnemental). Comme réboisement des jeunes plantes , elles sont des vastes terrains pour le réboisement . Leurs possession du Fleuve de DABARA peuvent changer beaucoup de chose , comme pour lutter contre la sécheresse , la restauration des fertilité de terre cultivable
C16: Sècheresse
C18: Ampleur | G18: Capacités (communauté, ménages, individus) | M18: Cote de capacité | P18: Valeur de CAP
C19: 1. Gestion des Risques de Catastrophe | M19: AUCUNE capacité | P19: =IF(M19="---","",VLOOKUP(M19,$C$58:$D$61,2,FALSE)) -> #N/A
C20: 2. Santé | G20: AC, médecin | M20: Capacité MOYENNE | P20: =IF(M20="---","",VLOOKUP(M20,$C$58:$D$61,2,FALSE)) -> #N/A
C21: 3. Eau et assainissement | G21: > Pompe > la communauté a accès à l'eau potable | M21: Capacité MOYENNE | P21: =IF(M21="---","",VLOOKUP(M21,$C$58:$D$61,2,FALSE)) -> #N/A
C22: 4.Logement | M22: AUCUNE capacité | P22: =IF(M22="---","",VLOOKUP(M22,$C$58:$D$61,2,FALSE)) -> #N/A
C23: 5. Alimentation et nutrition | G23: Pratique de culture capable de résisté la sècheresse | M23: Capacité MOYENNE | P23: =IF(M23="---","",VLOOKUP(M23,$C$58:$D$61,2,FALSE)) -> #N/A
C24: 6. Opportunités économiques | G24: cultures résistantes à la sécheresse | M24: Capacité MOYENNE | P24: =IF(M24="---","",VLOOKUP(M24,$C$58:$D$61,2,FALSE)) -> #N/A
C25: 7. Infrastructure et services | M25: Capacité ELEVEE | P25: =IF(M25="---","",VLOOKUP(M25,$C$58:$D$61,2,FALSE)) -> #N/A
C26: 8. Gestion des ressources naturelles | G26: possession mer | M26: Capacité ELEVEE | P26: =IF(M26="---","",VLOOKUP(M26,$C$58:$D$61,2,FALSE)) -> #N/A
C27: 6. Social cohesion & Inclusion | G27: =#REF! -> #REF! | M27: =#REF! -> #REF! | P27: =IF(M27="---","",VLOOKUP(M27,$C$58:$D$61,2,FALSE)) -> #REF!
C28: 7. Connectedness | G28: =#REF! -> #REF! | M28: =#REF! -> #REF! | P28: =IF(M28="---","",VLOOKUP(M28,$C$58:$D$61,2,FALSE)) -> #REF!
C30: ='3. Dangers'!M16 -> Innondation
C32: Ampleur | G32: Capacités (communauté, ménages, individus) | M32: Cote de capacité | P32: Valeur de CAP
C33: 1. Gestion des Risques de Catastrophe | G33: information médiatique, paiby | M33: AUCUNE capacité | P33: =IF(M33="---","",VLOOKUP(M33,$C$58:$D$61,2,FALSE)) -> #N/A
C34: 2. Santé | G34: Agents communautaires , Médecin CSB | M34: Capacité ELEVEE | P34: =IF(M34="---","",VLOOKUP(M34,$C$58:$D$61,2,FALSE)) -> #N/A
C35: 3. Eau et assainissement | G35: Pompe et source d'eau | M35: Capacité MOYENNE | P35: =IF(M35="---","",VLOOKUP(M35,$C$58:$D$61,2,FALSE)) -> #N/A
C36: 4.Logement | M36: AUCUNE capacité | P36: =IF(M36="---","",VLOOKUP(M36,$C$58:$D$61,2,FALSE)) -> #N/A
C37: 5. Alimentation et nutrition | M37: AUCUNE capacité | P37: =IF(M37="---","",VLOOKUP(M37,$C$58:$D$61,2,FALSE)) -> #N/A
C38: 6. Opportunités économiques | G38: disponibilité de cultivé | M38: AUCUNE capacité | P38: =IF(M38="---","",VLOOKUP(M38,$C$58:$D$61,2,FALSE)) -> #N/A
C39: 7. Infrastructure et services | G39: borne fontaine | M39: Capacité MOYENNE | P39: =IF(M39="---","",VLOOKUP(M39,$C$58:$D$61,2,FALSE)) -> #N/A
C40: 8. Gestion des ressources naturelles | G40: plantes médicinales, Mangrove | M40: Capacité MOYENNE | P40: =IF(M40="---","",VLOOKUP(M40,$C$58:$D$61,2,FALSE)) -> #N/A
C41: 6. Social cohesion & Inclusion | G41: =G27 -> #REF! | M41: =#REF! -> #REF! | P41: =IF(M41="---","",VLOOKUP(M41,$C$58:$D$61,2,FALSE)) -> #REF!
C42: 7. Connectedness | G42: =G28 -> #REF! | M42: =M28 -> #REF! | P42: =IF(M42="---","",VLOOKUP(M42,$C$58:$D$61,2,FALSE)) -> #REF!
C44: ='3. Dangers'!C32 -> Epidémies
C46: Ampleur | G46: Capacités (communauté, ménages, individus) | M46: Cote de capacité | P46: Valeur de CAP
C47: 1. Gestion des Risques de Catastrophe | G47: Disponibilité des moyens de communication et téléphonique, Paiby | M47: AUCUNE capacité | P47: =IF(M47="---","",VLOOKUP(M47,$C$58:$D$61,2,FALSE)) -> #N/A
C48: 2. Santé | G48: Agents communautaires , Médecin CSB | M48: Capacité ELEVEE | P48: =IF(M48="---","",VLOOKUP(M48,$C$58:$D$61,2,FALSE)) -> #N/A
C49: 3. Eau et assainissement | G49: Pompe et source d'eau | M49: Capacité ELEVEE | P49: =IF(M49="---","",VLOOKUP(M49,$C$58:$D$61,2,FALSE)) -> #N/A
C50: 6. Opportunités économiques | M50: Capacité ELEVEE
C51: 7. Infrastructure et services | G51: CSB, Pompe | M51: Capacité ELEVEE | P51: =IF(M51="---","",VLOOKUP(M51,$C$58:$D$61,2,FALSE)) -> #N/A
C52: 8. Gestion des ressources naturelles | G52: plantes médicinales, Mangrove | M52: Capacité ELEVEE | P52: =IF(M52="---","",VLOOKUP(M52,$C$58:$D$61,2,FALSE)) -> #N/A
C53: 6. Social cohesion & Inclusion | G53: =G41 -> #REF! | M53: =M41 -> #REF! | P53: =IF(M53="---","",VLOOKUP(M53,$C$58:$D$61,2,FALSE)) -> #REF!
...

Sheet 6. Cohésion, Inclusion, Connect
A1: Évaluation des Vulnérabilités et des Capacités Améliorée (EVCa) | Synthèse
A4: Informations générales
E5: ='1. Résumé'!E6 -> FKT 09/12 Manometinay | K5: ='1. Résumé'!G8 -> Pays : Madagascar | R5: ='1. Résumé'!E10 -> Société nationale : Croix-Rouge Malagasy
A8: 5. Cote de RISQUE pour la cohésion sociale, l'inclusion et la connectivité
C10: Si nécessaire, ajoutez une brève analyse globale de ces dimensions de résilience ci-dessous.
C12: La cohesion sociale est une question dificile à poser, mais après discution entre les membres du fokontany, on sent de l'entraide en temps d'urgence dans le fokontany
C14: Cote de RISQUE pour la cohésion sociale, l'inclusion et la connectivité pour l'ensemble de la communauté
C15: Fournissez des détails à partir des diagrammes de Venn afin d’expliquer les classements.
C16: Cohésion sociale | G16: Les gens ne s'entraident pas dans la communauté en temps d'urgence et en temps normal, | S16: ELEVEE | T16: =IF(S16="---","",VLOOKUP(S16,$C$22:$D$25,2,FALSE)) -> 1
C17: Inclusion | G17: L'inclusion n'est pas respecté dans la communauté en temps d'urgence et en temps normal | S17: FAIBLE | T17: =IF(S17="---","",VLOOKUP(S17,$C$22:$D$25,2,FALSE)) -> 0.33
C18: Connectivité | G18: Indisponibilité de connectivité avec l'exterieur | S18: FAIBLE | T18: =IF(S18="---","",VLOOKUP(S18,$C$22:$D$25,2,FALSE)) -> 0.33
C22: ELEVEE | D22: 1
C23: MOYENNE | D23: 0.67
C24: FAIBLE | D24: 0.33

Sheet 7. Risque
A1: Évaluation des Vulnérabilités et des Capacités Améliorée (EVCa) | Synthèse
A4: Informations générales
E5: ='1. Résumé'!E6 -> FKT 09/12 Manometinay
A8: 8. Risque
C10: Les tableaux ci-dessous présentent un résumé des notes que vous avez fournies dans les feuilles précédentes. Sur cette base, les scores de risque ont été calculés et sont affichés à droite. Pour le risque global, référez-vous au bas de ce tableau.
C12: ='3. Dangers'!C16 -> Sècheresse
U13: Vulnerability
C14: Ampleur | H14: VUL (0.00 à 1.00) | J14: CAP (0.00 à 1.00) | M14: Cote de RISQUE | U14: No | V14: Low | W14: Moderate | X14: High
C15: 1. Gestion des Risques de Catastrophe | H15: ='4. Vulnérabilité'!V29 -> #N/A | J15: ='5. Capacité'!P19 -> #N/A | M15: =IF(AND(H15<>"",J15<>""),IF((H15-J15)<-0.32,"LOW",IF((H15-J15)<0.33,"MODERATE","HIGH")),"") -> #N/A | S15: Capacity | U15: 0 | V15: 0.33 | W15: 0.67 | X15: 1
C16: 2. Santé | H16: ='4. Vulnérabilité'!V30 -> #N/A | J16: ='5. Capacité'!P20 -> #N/A | M16: =IF(AND(H16<>"",J16<>""),IF((H16-J16)<-0.33,"LOW",IF((H16-J16)<0.32,"MODERATE","HIGH")),"") -> #N/A | S16: High | T16: 1 | U16: LOW | V16: LOW | W16: LOW | X16: MODERATE
C17: 3. Eau et assainissement | H17: ='4. Vulnérabilité'!V31 -> #N/A | J17: ='5. Capacité'!P21 -> #N/A | M17: =IF(AND(H17<>"",J17<>""),IF((H17-J17)<-0.33,"LOW",IF((H17-J17)<0.32,"MODERATE","HIGH")),"") -> #N/A
C18: 4.Logement | H18: ='4. Vulnérabilité'!V32 -> #N/A | J18: ='5. Capacité'!P22 -> #N/A | M18: =IF(AND(H18<>"",J18<>""),IF((H18-J18)<-0.33,"LOW",IF((H18-J18)<0.32,"MODERATE","HIGH")),"") -> #N/A
C19: 5. Alimentation et nutrition | H19: ='4. Vulnérabilité'!V33 -> #N/A | J19: ='5. Capacité'!P23 -> #N/A | M19: =IF(AND(H19<>"",J19<>""),IF((H19-J19)<-0.33,"LOW",IF((H19-J19)<0.32,"MODERATE","HIGH")),"") -> #N/A
C20: 6. Opportunités économiques | H20: ='4. Vulnérabilité'!V34 -> #N/A | J20: ='5. Capacité'!P24 -> #N/A | M20: =IF(AND(H20<>"",J20<>""),IF((H20-J20)<-0.33,"LOW",IF((H20-J20)<0.32,"MODERATE","HIGH")),"") -> #N/A | S20: Moderate | T20: 0.67 | U20: LOW | V20: LOW | W20: MODERATE | X20: HIGH
C21: 7. Infrastructure et services | H21: ='4. Vulnérabilité'!V35 -> #N/A | J21: ='5. Capacité'!P25 -> #N/A | M21: =IF(AND(H21<>"",J21<>""),IF((H21-J21)<-0.33,"LOW",IF((H21-J21)<0.32,"MODERATE","HIGH")),"") -> #N/A | S21: Low | T21: 0.33 | U21: LOW | V21: MODERATE | W21: HIGH | X21: HIGH
C22: 8. Gestion des ressources naturelles | H22: ='4. Vulnérabilité'!V36 -> #N/A | J22: ='5. Capacité'!P26 -> #N/A | M22: =IF(AND(H22<>"",J22<>""),IF((H22-J22)<-0.33,"LOW",IF((H22-J22)<0.32,"MODERATE","HIGH")),"") -> #N/A | S22: No | T22: 0 | U22: MODERATE | V22: HIGH | W22: HIGH | X22: HIGH
C23: 9. Cohésion sociale | H23: N/D | J23: N/D | M23: ='6. Cohésion, Inclusion, Connect'!S16 -> ELEVEE
C24: 10. Inclusion | H24: N/D | M24: ='6. Cohésion, Inclusion, Connect'!S17 -> FAIBLE
C25: 11. Connectivité | H25: N/D | J25: N/D | M25: ='6. Cohésion, Inclusion, Connect'!S18 -> FAIBLE
C27: ='3. Dangers'!M16 -> Innondation | U27: No | V27: Low | W27: Moderate | X27: High
S28: Capacity | U28: 0 | V28: 0.33 | W28: 0.67 | X28: 1
C29: Ampleur | H29: VUL | J29: CAP | M29: Cote de RISQUE | S29: High | T29: 1 | U29: =U28-T29 -> -1 | V29: =V28-T29 -> -0.67 | W29: =W28-T29 -> -0.33 | X29: =X28-T29 -> 0
C30: 1. Gestion des Risques de Catastrophe | H30: ='4. Vulnérabilité'!V42 -> #N/A | J30: ='5. Capacité'!P33 -> #N/A | M30: =IF(AND(H30<>"",J30<>""),IF((H30-J30)<-0.32,"LOW",IF((H30-J30)<0.33,"MODERATE","HIGH")),"") -> #N/A | S30: Moderate | T30: 0.67 | U30: =U28-T30 -> -0.67 | V30: =V28-T30 -> -0.34 | W30: =W28-T30 -> 0 | X30: =X28-T30 -> 0.33
C31: 2. Santé | H31: ='4. Vulnérabilité'!V43 -> #N/A | J31: ='5. Capacité'!P34 -> #N/A | M31: =IF(AND(H31<>"",J31<>""),IF((H31-J31)<-0.32,"LOW",IF((H31-J31)<0.33,"MODERATE","HIGH")),"") -> #N/A | S31: Low | T31: 0.33 | U31: =U28-T31 -> -0.33 | V31: =V28-T31 -> 0 | W31: =W28-T31 -> 0.34 | X31: =X28-T31 -> 0.67
C32: 3. Eau et assainissement | H32: ='4. Vulnérabilité'!V44 -> #N/A | J32: ='5. Capacité'!P35 -> #N/A | M32: =IF(AND(H32<>"",J32<>""),IF((H32-J32)<-0.32,"LOW",IF((H32-J32)<0.33,"MODERATE","HIGH")),"") -> #N/A
C33: 4.Logement | H33: ='4. Vulnérabilité'!V45 -> #N/A | J33: ='5. Capacité'!P36 -> #N/A | M33: =IF(AND(H33<>"",J33<>""),IF((H33-J33)<-0.32,"LOW",IF((H33-J33)<0.33,"MODERATE","HIGH")),"") -> #N/A
C34: 5. Alimentation et nutrition | H34: ='4. Vulnérabilité'!V46 -> #N/A | J34: ='5. Capacité'!P37 -> #N/A | M34: =IF(AND(H34<>"",J34<>""),IF((H34-J34)<-0.32,"LOW",IF((H34-J34)<0.33,"MODERATE","HIGH")),"") -> #N/A
C35: 6. Opportunités économiques | H35: ='4. Vulnérabilité'!V47 -> #N/A | J35: ='5. Capacité'!P38 -> #N/A | M35: =IF(AND(H35<>"",J35<>""),IF((H35-J35)<-0.32,"LOW",IF((H35-J35)<0.33,"MODERATE","HIGH")),"") -> #N/A | S35: No | T35: 0 | U35: 0 | V35: =V28-T35 -> 0.33 | W35: =W28-T35 -> 0.67 | X35: =X28-T35 -> 1
C36: 7. Infrastructure et services | H36: ='4. Vulnérabilité'!V48 -> #N/A | J36: ='5. Capacité'!P39 -> #N/A | M36: =IF(AND(H36<>"",J36<>""),IF((H36-J36)<-0.32,"LOW",IF((H36-J36)<0.33,"MODERATE","HIGH")),"") -> #N/A
C37: 8. Gestion des ressources naturelles | H37: ='4. Vulnérabilité'!V49 -> #N/A | J37: ='5. Capacité'!P40 -> #N/A | M37: =IF(AND(H37<>"",J37<>""),IF((H37-J37)<-0.32,"LOW",IF((H37-J37)<0.33,"MODERATE","HIGH")),"") -> #N/A
C38: 9. Cohésion sociale | H38: N/D | J38: N/D | M38: =M23 -> ELEVEE
C39: 10. Inclusion | M39: =M24 -> FAIBLE
C40: 11. Connectivité | H40: N/D | J40: N/D | M40: =M25 -> FAIBLE
C42: ='3. Dangers'!C32 -> Epidémies
C44: Ampleur | H44: VUL | J44: CAP | M44: Cote de RISQUE
C45: 1. Gestion des Risques de Catastrophe | H45: ='4. Vulnérabilité'!V54 -> #N/A | J45: ='5. Capacité'!P47 -> #N/A | M45: =IF(AND(H45<>"",J45<>""),IF((H45-J45)<-0.32,"LOW",IF((H45-J45)<0.33,"MODERATE","HIGH")),"") -> #N/A
C46: 2. Santé | H46: ='4. Vulnérabilité'!#REF! -> #REF! | J46: ='5. Capacité'!P48 -> #N/A | M46: =IF(AND(H46<>"",J46<>""),IF((H46-J46)<-0.32,"LOW",IF((H46-J46)<0.33,"MODERATE","HIGH")),"") -> #REF!
C47: 3. Eau et assainissement | H47: ='4. Vulnérabilité'!V56 -> #N/A | J47: ='5. Capacité'!P49 -> #N/A | M47: =IF(AND(H47<>"",J47<>""),IF((H47-J47)<-0.32,"LOW",IF((H47-J47)<0.33,"MODERATE","HIGH")),"") -> #N/A
C48: 4.Logement | H48: ='4. Vulnérabilité'!V57 -> #N/A | J48: ='5. Capacité'!#REF! -> #REF! | M48: =IF(AND(H48<>"",J48<>""),IF((H48-J48)<-0.32,"LOW",IF((H48-J48)<0.33,"MODERATE","HIGH")),"") -> #N/A
C49: 5. Alimentation et nutrition | H49: ='4. Vulnérabilité'!V58 -> #N/A | J49: ='5. Capacité'!#REF! -> #REF! | M49: =IF(AND(H49<>"",J49<>""),IF((H49-J49)<-0.32,"LOW",IF((H49-J49)<0.33,"MODERATE","HIGH")),"") -> #N/A
...

Sheet 8. Analyse
A1: Évaluation des Vulnérabilités et des Capacités Améliorée (EVCa) | Synthèse
A4: Informations générales
E5: ='1. Résumé'!E6 -> FKT 09/12 Manometinay | J5: ='1. Résumé'!G8 -> Pays : Madagascar
A8: 2. Informations consolidées sur les risques - complétez cette section comme un résumé global à la fin du processus d'évaluation
C10: Pour chaque dimension identifiée comme présentant un risque élevé (et potentiellement moyen), regroupez les détails/informations relatifs à la vulnérabilité et à la capacité dans le tableau ci-dessous (c'est-à-dire copiez/collez les détails et informations relatifs à la vulnérabilité et à la capacité pour chaque dimension élevée (et potentiellement moyenne) des tableaux ci-dessus) . Référez-vous aux directives EVCa à la page 43.
C12: Danger | G12: Ampleur | J12: Éléments de vulnérabilité | L12: Éléments de capacité | N12: Résumé des risques clés
J13: Copiez le texte pertinent de la section 6 | L13: Copiez le texte pertinent de la section 7
C14: Innondation | G14: 1. Gestion de la connaissance des risques | J14: La population ont du mal a etre bien informé en raison de l'inéxistance des ELS biens equipés et des outils SAP; ceci les rend toujours vulnérables et sans préparation à la résilience | L14: information médiatique, paiby | N14: Dégats matérieles ,dégats environnementaux et surtout dégats humains
C15: Epidémies | G15: 2. Santé | J15: Auto-médecine, manque de médecin dans la communauté le rend vulnérable et entrainant la propagation de l'épidémie causé par la pollution | L15: Agents communautaires ,Médecin, CSB | N15: perte Humaine, aggravisation des maladie
C16: Cyclone | G16: 1. Gestion de la connaissance des risques | J16: La population ont du mal a etre bien informé en raison de l'inéxistance des ELS biens equipés et des outils SAP; ceci les rend toujours vulnérables et sans préparation à la résilience | L16: information médiatique, paiby
C17: Sècheresse | G17: 6. Opportunités économiques | J17: difficulté de cultivé; baisse de revenu | L17: Pompe et source d'eau
A26: 2. Analyse des risques
C28: Résumez ci-dessous l’analyse globale.
C30: Le cyclone est une catastrophe progressive qui touche la communauté. Les vulnérabilités multiples (sociales, économiques, environnementales) se combinent pour aggraver ses impacts. Une gestion proactive, comprenant des systèmes d’alerte, des politiques durables et des infrastructures adaptées, est essentielle pour réduire ces vulnérabilités. En somme, il est crucial de renforcer la résilience des communautés face à la sécheresse en intégrant des approches multisectorielles et inclusives dans la gestion des risques de catastrophes.
G33: Liste déroulante
G34: 1. Gestion de la connaissance des risques
G35: 2. Santé
G36: 3. Eau et assainissement
G37: 4. Logement
G38: 5. Alimentation et nutrition
G39: 6. Opportunités économiques
G40: 7. Infrastructures et services
G41: 8. Gestion des ressources naturelles
G42: 9. Cohésion sociale
G43: 10. Inclusion
G44: 11. Connectivité

Sheet 9. Plan d’action
A1: Évaluation des Vulnérabilités et des Capacités Améliorée (EVCa) | Synthèse
E4: ='1. Résumé'!E6 -> FKT 09/12 Manometinay | I4: ='1. Résumé'!E10 -> Société nationale : Croix-Rouge Malagasy
A7: 9. Plan d’action
C9: Énumérez les activités de réduction des risques telles que priorisées par la communauté (détail du calendrier de mise en œuvre en pièce jointe). Référez-vous aux directives EVCa à la page 46.
C11: Risques prioritaires | E11: Résultats | G11: Activité/résultat prioritaire | I11: Ressources nécessaires (intrants) et manière de les obtenir | K11: Support technique nécessaire | M11: Période | O11: Qui sera responsable ?
C13: Sècheresse | E13: Dimunition des risques , des dégats materiels, humaines et environnemental , préparation nutritionnelle et financieres,avoir un peu de tranquilité pendant l'urgence | G13: Formation en agriculture adapté à la sècheresse, approvisionnement de médicament au AC, graine; sensibilisation de reboisement, approvisionement d'eau potable dans les campements | I13: materiaux de construction et des ouvriers, pépinières, collaboration avec les organismes environnemental ET TéLECOMMUNICATION comme : MNP , WWF , DREDD , YAS, ORAGE, AIRTEL etc | K13: soutien financier et technique | M13: Mars - Avril | O13: Chef Fokontany , Comite EVCA, directeur d'école
C15: Epidemie | E15: réduction de taux des malades ,des mortalités due à l'épidemie | G15: Approvisionnement de médicament, traitement d'eau, formation des AC, Sensibilisation alimentaire | I15: collaboration avec les organismes de la santé publique: DRS, ONN, Commerce | K15: Appui technique | M15: Toute l'année | O15: Chef Fokontany , AC
C17: Innondation | E17: Dimunition des risques , des dégats materiels, humaines et environnemental , préparation nutritionnelle et financieres,avoir un peu de tranquilité avoir un peu de tranquilité pendant l'urgence | G17: constitution d'une équipe local de secour et approsionnement de leur Equipement et outils d'alerte; equipement des AC et agriculture, formation environnementale | I17: Préparation précoce , Formation des Equipe Local des Sécours (ELS), Téchniciens specialistes en environnement , collaboration avec les organismes environnemental et GRC locaux comme : MNP , WWF , DREDD , BNGRC etc | K17: Sensibilisations , formations, appui technique et financier | M17: Mars - Novembre | O17: Chef fokontany , Commite EVCA
C19: Cyclone | E19: Dimunition des risques , des dégats materiels, humaines et environnemental , préparation nutritionnelle et financieres,avoir un peu de tranquilité avoir un peu de tranquilité pendant l'urgence | G19: constitution d'une équipe local de secour et approsionnement de leur Equipement et outils d'alerte; equipement des AC et agriculture et peche, approsionnement des pépinières | I19: Préparation précoce , Formation des Equipe Local des Sécours (ELS), Téchniciens specialistes en environnement , collaboration avec les organismes environnemental et GRC locaux comme : MNP , WWF , DREDD , BNGRC etc | K19: Sensibilisations , formations, appui technique et financier | M19: Mars - Novembre | O19: Chef fokontany , Commite EVCA
C33: Validation du plan d’action
C35: Représentant de la communauté | E35: Bureau national des Catastrophes | G35: Représentant des parties prenantes | I35: SN ou branche
E36: BNGRC | I36: Croix-Rouge Malagasy/Branche Menabe

Sheet Feuil1
