Workbook
Name Drop_down2: '8. Analyse'!#REF!
Name Drop_down2: '8. Analyse'!#REF!
Name Hazards: '3. Dangers'!$AA$2:$AA$5

Sheet 1. Résumé
A1: Évaluation des Vulnérabilités et des Capacités Améliorée (EVCa) | Synthèse
A3: Aperçu
A5: Informations générales
E6: FKT 04/18_Tanambao | G6: Quartiers : Fkt 04/18 Tanambao
E8: Province / État : Toliara | G8: Pays : Madagascar
E10: Société nationale : Croix-Rouge Malagasy | G10: Branche : Morondava
E12: Date de début de l’EVCa : 11/11/2024 | G12: Contact : 0348736810
E14: Date de fin de l’EVCa : 13/11/2024 | G14: Position : Président de District
E16: Coordonnées GPS de la communauté | G16: Courriel
A19: 1.a Résumé analytique
C21: Incluez la manière et le processus avec lesquels la communauté a été sélectionnée.
C22: L'EVCa consiste en un processus participatif d'évaluation des risques communautaires développé afin que les communautés acquièrent davantage de résilience à travers l'évaluation et l'analyse des dangers qui les menacent et l'identification de solutions.
C24: Dans le cadre du projet Programme local de Préparation et de Résilience aux aléas Multiples (PPRM) financé par la FCDO mis en oeuvre par la Croix-Rouge Malagasy , des activités de préparation et anticipation ont identifiés comme besoin crucial pour préparer cette saison cyclonique 2024– 2025. Ainsi, la région Menabe-Madagascar a été identifiée comme zone favorable pour mener une Evaluation des Vulnérabilités et Capacités améliorée (EVCA).Un atelier EVCA de trois (03) jours par Fokontany est ainsi organisé dans 04 fokontany de la ville de Morondava et 02 fokontany pour la commune d'Analaiva. La méthodologie adoptée pour l'identification des représentants des communautés sélectionnées à été la suivante : approche participative avec implication et responsabilisation de la communauté qui se voit chargée de désigner les représentants des différentes entités présentes dans les Fokontany afin que ces derniers participent à l'atelier. Cette phase s'est déroulée sur trois jours et doit faire émerger les 20 représentants de la communauté présents à l'EVCA en incluant les secteurs pouvant être affectés par le passage d'un aléas, à savoir : l’éducation, la santé, eau et assainissement, le logement, la nourriture et la sécurité alimentaire, les infrastructures et services, la gestion des ressources naturelles, et la sécurité. L'identification de ces représentants s'est faite lors d'une réunion communautaire. Les participants identifiés ont été les suivants : - Représentant du FKT (Vice president Fokontany) en tant qu’observateurs - Représentant de la CRM local - Représentant des personnes âgées - Représentant des Jeunes - Représentant des Femmes - Représentant de la société civile - Représentant du secteur éducation - Représentant des commerçants - Représentant du pecheurs - Représentant des cultivateurs - Agent communautaire
K35: Valeurs clés (non imprimées). Référez-vous à la feuille 8 pour les risques et à la feuille 12 pour la résilience.
A36: 1.b Modèle de risque | L36: Danger 1
C39: ='3. Dangers'!C16:K16 -> Inondation
C40: Ampleur | E40: Cote de risque
C41: 1. Gestion des Risques de Catastrophe | E41: ELEVEE
C42: 2. Santé | E42: ELEVEE
C43: 3. Eau et assainissement | E43: ELEVEE
C44: 4. Logement | E44: MOYENNE
C45: 5. Alimentation et nutrition | E45: MOYENNE
C46: 6. Cohésion sociale | E46: ELEVEE
C47: 7. Inclusion | E47: MOYENNE
C48: 8. Opportunités économiques | E48: MOYENNE
C49: 9. Infrastructure et services | E49: MOYENNE
C50: 10. Gestion des ressources naturelles | E50: MOYENNE
C51: 11. Connectivité | E51: MOYENNE
C53: ='[1]3. Dangers'!M16 -> Cyclone
C54: Ampleur | E54: Cote de risque
C55: 1. Gestion des Risques de Catastrophe | E55: ELEVEE
C56: 2. Santé | E56: ELEVEE
C57: 3. Eau et assainissement | E57: MOYENNE
C58: 4. Logement | E58: ELEVEE
C59: 5. Alimentation et nutrition | E59: MOYENNE
C60: 6. Cohésion sociale | E60: ELEVEE
C61: 7. Inclusion | E61: ='[1]7. Risque'!$M$39 -> MOYENNE
C62: 8. Opportunités économiques | E62: ELEVEE
C63: 9. Infrastructure et services | E63: ELEVEE
C64: 10. Gestion des ressources naturelles | E64: MOYENNE
...

Sheet 2. Contexte
A1: Évaluation des Vulnérabilités et des Capacités Améliorée (EVCa) | Synthèse
A3: Informations contextuelles
A5: Informations générales
E6: ='1. Résumé'!E6 -> FKT 04/18_Tanambao | K6: Madagascar | R6: Croix-Rouge Malagasy
A9: 3. Description et contexte de la communauté
C11: Fournissez un bref aperçu de la communauté.
C13: Morondava, chef-lieu de la région Menabe ,province de Toliara, est la seconde ville du pays et concentre 6,6% de sa population urbaine. Elle se situe dans la région Menabe, sur la côte-ouest du pays, au débouché de l'océan indien , axe majeur de transport de marchandises, à environ 697 kilomètres d’Antananarivo via la route nationale 35 et 7 (RN 35 et RN7). Morondava est composée de 4 commune et de 18 fokontany et rassemble 22% de la population de la région Menabe, avec 178 966 habitants pour une superficie de 28km22, soit une densité moyenne de 10 534 habitants/km2. Principal port du pays et parmi les plus importants de l’océan Indien, la ville est un lieu de transit de marchandises et de tourisme et son économie est majoritairement basée sur la pêche ainsi que sur l’agriculture, rendant les populations fortement dépendantes des ressources naturelles dont elles disposent. La ville de Morondava est caractérisée par un climat tropical chaud et humide avec une saison chaude et pluvieuse entre novembre et avril. La ville de Morondava est particulièrement vulnérable aux cyclones en raison de sa position géographique et de son élévation basse. Les sols, sablonneux et argileux, ne sont que très peu perméables, générant des problèmes d’évacuation des eaux. La ville, de par sa position géographique et sa densité de population, est particulièrement vulnérable aux aléas climatiques. Ces derniers ont d’importants impacts sur les lieux d’implantation humaine mais également sur les sites de production économique ou de culture, exposant les communautés à des risques d’insécurité alimentaire. Les habitants disposent généralement d’une capacité d’adaptation limitée en raison du niveau de pauvreté et du manque d’infrastructures. La ville de Morondava ne compte par exemple que six centres de santé de base et deux centres hospitaliers universitaires pour une population de près de 178 966 habitants. Entre 1982 et 2018, la région Menabe a été touchée par 32 cyclones, dont plusieurs ont été qualifiés de cyclones tropicaux en raison de leur intensité. Morondava se trouve ainsi être la ville la plus exposée au risque de pertes directes dues aux cyclones tropicaux, avec des pertes annuelles moyennes estimées à 20 millions de dollars. En plus d’affecter les populations, leurs habitations et moyens de subsistance, les cyclones peuvent perturber les importations, notamment de combustibles fossiles, limitant temporairement la production thermique à l’échelle nationale. Les inondations sont également très fréquentes dans la ville de Morondava et impactent principalement les habitations. L’immense majorité des pertes directes dues aux cyclones et inondations concernent le secteur résidentiel - respectivement 53 et 66%. Ces phénomènes peuvent également avoir des conséquences sur la santé des populations, exposant les communautés à de nombreux risques de maladies gastro-intestinales liées aux eaux stagnantes ou à la contamination des eaux de boisson. En outre, la zone est sujette à l’érosion marine et terrestre, dont l’accélération progressive a généré l’ensablement de la rade du port. Ces phénomènes météorologiques extrêmes, leur intensité, récurrence et effets néfastes se trouvent exacerbés par le réchauffement climatique. Morondava est aujourd’hui confrontée à une hausse de ses températures, à une élévation du niveau de la mer et à une perturbation du régime pluviométrique. Le modèle climatique médian prévoit par exemple une élévation du niveau de la mer de 11 centimètres d’ici 2030 et de 43 centimètres d’ici 2080 pour les côtes malgaches. Ce phénomène pourrait générer une intrusion saline dans les terres, les eaux souterraines et les zones humides littorales, ce qui représente une menace élevée pour les communautés côtières de la ville, leurs activités agricoles et leur approvisionnement en eau potable mais également pour les écosystèmes. Ainsi, tous ces risques hydro climatiques et environnementaux ont des répercussions majeures sur les populations et leurs moyens de subsistance, leur habitat et les besoins relatifs à l’eau, l’assainissement et à la santé. De manière plus spécifique, le Fokontany 04/18 Tanambao (secteurs 1, 2, 3, 4, 5) est composé de la sorte Secteur 1 : population de 1252 habitants (466 hommes et 786 femmes) répartis en 1205 ménages avec une moyenne de 4 personnes par ménage Secteur 2 : population de 1181 habitants (470 hommes et 711 femmes) répartis en 1113 ménages avec une moyenne de 7 personnes par ménage Secteur 3 : population de 1208 habitants (483 hommes et 725 femmes) répartis en 1157 ménages avec une moyenne de 5 personnes par ménage Secteur 4 : population de 1261 habitants (419 hommes et 842 femmes) répartis en 1171 ménages avec une moyenne de 2 personnes par ménage Secteur 5 : population de 1288 habitants (581 hommes et 707 femmes) répartis en 1219 ménages avec une moyenne de 5 personnes par ménage Le fokontany 04/18Tanambao regroupe ainsi 6190 habitants dont 2 419 hommes et 3 771 femmes Les principaux risques auxquels fait face la communauté sont les suivants : inondations et cyclones en lien avec les canaux bouchés et la mauvaise gestion des déchets ce qui génère des maladies ainsi qu’en lien avec l’augmentation du niveau de la mer. Le fokontany a été touché par plusieurs cyclones depuis les années 1990, ainsi que par l'épidémie de Covid.
C15: 3a Population
C17: Répartition par sexe et tranche d'âge | E17: 0 - 5 ans | I17: 6 - 17 ans | M17: 18 - 65 ans | Q17: 66 ans et plus | U17: Total
E18: Hommes | F18: Femmes | G18: Sous-total | I18: Hommes | J18: Femmes | K18: Sous-total | M18: Hommes | N18: Femmes | O18: Sous-total | Q18: Hommes | R18: Femmes | S18: Sous-total | U18: Hommes | V18: Femmes | W18: Global
C20: Nombre de personnes Saisissez les données dans les cellules encadrées de rouge | E20: 154 | F20: 221 | G20: =SUM(E20:F20) -> 375 | I20: 271 | J20: 2011 | K20: =SUM(I20:J20) -> 2282 | M20: 1223 | N20: 2014 | O20: =SUM(M20:N20) -> 3237 | Q20: 66 | R20: 39 | S20: =SUM(Q20:R20) -> 105 | U20: 1714 | V20: 4285 | W20: =SUM(U20:V20) -> 5999
C22: Part des sexes par tranche d'âge (automatique) | E22: =E20/G20 -> 0.41066667 | F22: =F20/G20 -> 0.58933333 | G22: =SUM(E22:F22) -> 1 | I22: =I20/K20 -> 0.11875548 | J22: =J20/K20 -> 0.88124452 | K22: =SUM(I22:J22) -> 1 | M22: =M20/O20 -> 0.37781897 | N22: =N20/O20 -> 0.62218103 | O22: =SUM(M22:N22) -> 1 | Q22: =Q20/S20 -> 0.62857143 | R22: =R20/S20 -> 0.37142857 | S22: =SUM(Q22:R22) -> 1 | U22: =U20/W20 -> 0.28571429 | V22: =V20/W20 -> 0.71428571 | W22: =SUM(U22:V22) -> 1
C24: Nombre de personnes handicapées (estimation si les données ne sont pas disponibles) | E24: 0 | F24: 0 | G24: =SUM(E24:F24) -> 0 | I24: 0 | J24: 0 | K24: =SUM(I24:J24) -> 0 | M24: 8 | N24: 9 | O24: =SUM(M24:N24) -> 17 | Q24: 0 | R24: 0 | S24: =SUM(Q24:R24) -> 0 | U24: 8 | V24: 9 | W24: =SUM(U24:V24) -> 17
C26: Combien de personnes (approximativement) ont contribué à cette EVCa ? | U26: 11 | V26: 9 | W26: =SUM(U26:V26) -> 20
U27: =U26/U20 -> 0.0064177363 | V27: =V26/V20 -> 0.0021003501 | W27: =W26/W20 -> 0.003333889
C29: 3b Type de contexte Cette communauté se trouve-t-elle en milieu urbain, rural ou mixte ? | E29: Urbain | I29: 3c Environnement géophysique. Effectuez des sélections afin de décrire le cadre géophysique. | M29: Côtier | Q29: 3D Activités de subsistance Quelles sont les deux principales activités de subsistance dans cette communauté ? (Sélectionnez dans la liste) | U29: Pêche, pisciculture, collecte de produits aquatiques
M31: Terrain principalement plat | U31: Commerce
C33: Commentaires additionnels sur le type de contexte | E33: souvent touché par l'innondation | I33: Commentaires additionnels sur l’environnement géophysique | M33: Fokontany situé en plein ville ,Mais en basse altitude | Q33: Ajoutez d'autres activités de subsistance ici. | U33: Agriculture et fonctionnariat
A38: 3. Processus d’évaluation
C40: Décrivez le processus d’évaluation. (Période ? Personnes impliquées ? Parties prenantes impliquées ? Données secondaires et outils utilisés ?
C42: Les zones ont été choisi selon les résultats d'Enquetes et les critères de vulnérabilité que le projet a réalisée. Une fois les Fokontany identifiés, on a procédé à l'identification des personnes qui vont participer à l'atelier. pour cela, les critère sont comme suit: - Représentant du FKT (Chef Fokontany, chefs des hameaux) - Représentant des chretiens - Représentant de la CRM local - Représentant des personnes âgées - Représentant des Jeunes - Représentant des Femmes - Représentant des commerçants - Représentant de la société civile - Représentant du secteur éducation - Représentant du secteur eau - Représentant du secteur santé - Représentant des pecheurs - Agent communautaire Durant le processus, les autorités locales (Préfecture, Commune, Arrondissement) ainsi que le BNGRC, le MEN ainsi que les gouvernences locales ont été toujours impliqués.
C46: Liste déroulante 2b | E46: Liste déroulante 2d
C47: Urbain | E47: Production végétale et maraîchère
C48: Rural | E48: Production animale
C49: Mixte | E49: Pêche, pisciculture, collecte de produits aquatiques
C51: Liste déroulante 2c1 | E51: Fabrication
C52: Côtier | E52: Services
C53: Continental, avec d'importants fleuves | E53: Commerce
C54: Continental, dépourvu de fleuves importants
C56: Liste déroulante 2c2
C57: Terrain principalement plat
C58: Terrain principalement montagneux

Sheet 3. Dangers
A1: Évaluation des Vulnérabilités et des Capacités Améliorée (EVCa) | Synthèse | AA1: Dangers
AA2: =IF(E18="","",E18) -> Inondation
AA3: =IF(O18="","",O18) -> Cyclone
A4: Informations générales | AA4: =IF(E34="","",E34) -> Epidémies
E5: ='1. Résumé'!E6 -> FKT 04/18_Tanambao | K5: ='1. Résumé'!G8 -> Pays : Madagascar | R5: ='1. Résumé'!E10 -> Société nationale : Croix-Rouge Malagasy | AA5: =IF(O34="","",O34)
A8: 4. Dangers prioritaires
C10: Dans cette section, dressez la liste des dangers par ordre de priorité (en fonction de l'impact et de la fréquence passés et/ou des risques futurs) et de leurs caractéristiques. Référez-vous aux directives EVCa à la page 34
C12: Décrivez brièvement la base sur laquelle les dangers prioritaires ont été identifiés.
C14: Les dangers identifiés comme prioraitaires sont les suivants : inondation , épidémie ,cyclone. Les aléas ont été identifiés grace aux outils : profil historique, calendrier saisonnier, matrice des risques, cartographie, marche transversale
C16: Inondation | M16: Cyclone
C18: Nom/type de danger | E18: Inondation | M18: Nom/type de danger | O18: Cyclone
C20: Cause/origine : | E20: Débordement de rivière KABATOMENA dans la communauté ,Pluies, climat Caractéristiques des lieux , surtout la montée de la mer (marré Haute EQUINOX) Canal d'évacuation d'eau presque même niveau au surface de la communauté et trop étroits, déchets dans les canaux, construction dans les bas quartiers, manque d'action des responsables, pas assez d'infrastructure d'évacuation , en raison de sa position géographique et de son élévation basse manque d'action des responsables, pas assez d'infrastructure d'évacuation , | M20: Cause/origine : | O20: Changement climatique, perturbation ou dépression tropicale
C22: Signes précurseurs : | E22: Pluies , augmentation de niveau d'eau sur le Balise | M22: Signes précurseurs : | O22: vent , nuageux , tourbions , tempete , information de Météo
C24: Délai : | E24: 1 à 5 jours | M24: Délai : | O24: 1 à 5 jours
C26: Fréquence : | E26: saisonier | M26: Fréquence : | O26: chaque année
C28: Période d’occurrence : | E28: Décembre-Mars | M28: Période d’occurrence : | O28: Décembre -Mars
C30: Durée : | E30: 3 mois | M30: Durée : | O30: 4 mois
C32: Epidémies
C34: Nom/type de danger | E34: Epidémies
C36: Cause/origine : | E36: déversement des déchet ; Innondation , Défécation dans la nature , saleté , permanence d'eau resté dans la communauté
C38: Signes précurseurs : | E38: augmentation des effectifs des malades journalieres a meme symptome , toux , diarrhée , maux de tete récurente , maux de tete , Fièvre, toux, congestion nasale, difficultés respiratoires , emporté par le vent
C40: Délai : | E40: Non définie
C42: Fréquence : | E42: Récurente
C44: Période d’occurrence : | E44: Toute l'année
C46: Durée : | E46: Pas précis
C48: Combien de dangers prioritaires avez-vous inclus ci-dessus (minimum 1, maximum 3) ? | V48: 3

Sheet 4. Vulnérabilité
A1: Évaluation des Vulnérabilités et des Capacités Améliorée (EVCa) | Synthèse
A4: Informations générales
E5: ='1. Résumé'!E6 -> FKT 04/18_Tanambao | K5: ='1. Résumé'!G8 -> Pays : Madagascar | R5: ='1. Résumé'!E10 -> Société nationale : Croix-Rouge Malagasy
A8: 6. Vulnérabilité
C10: Si nécessaire, ajoutez une brève analyse globale de la vulnérabilité ci-dessous.
C12: Il y avait des représentants des hommes , des représentants des femmes, des représentants des jeunes. Ces derniers nous ont expliqué qu'il n'y avait pas de vulnérabilité particulière pour ces groupes ou de genre car toute la communauté est affectée et se débrouille eux meme .
A14: ] | C14: Qu'est-ce qui rend la communauté, ou des groupes particuliers au sein de la communauté, vulnérables ? Identifiez les groupes vulnérables au sein de votre communauté. | M14: Qu’est-ce qui les rend vulnérables ? Énumérez les vulnérabilités particulières pour chacun des groupes.
C16: Groupe vulnérable 1 | E16: Enfants : Ils dépendent des adultes pour leur sécurité et sont particulièrement exposés aux maladies, à la malnutrition ou au stress en cas de crise. | M16: Groupe vulnérable 1 | O16: Des facteurs liés à des aspects sociaux
C18: Groupe vulnérable 2 | E18: Femmes et filles : Elles subissent souvent des charges sociales et économiques disproportionnées et sont parfois exposées à des risques accrus de violence ou de discrimination en situation de crise. | M18: Groupe vulnérable 2 | O18: Des facteurs liés à des aspects sociaux
C20: Groupe vulnérable 3 | M20: Groupe vulnérable 3
C22: Groupe vulnérable 4 | M22: Groupe vulnérable 4
C24: ='3. Dangers'!C16 -> Inondation
C26: Énumérez et décrivez les impacts (passés et futurs), les aspects de vulnérabilité (y compris les causes profondes) et le niveau (élevé, moyen, faible) de vulnérabilité en utilisant les dimensions clés de la résilience. Référez-vous aux directives EVCa à la page 39.
C28: Ampleur | G28: Impact (passé et futur) | M28: Aspects de vulnérabilité avec leurs causes (la raison pour laquelle l'impact se produit et les causes profondes) | S28: Cote de vulnérabilité (choisissez dans la liste) | V28: Valeur de VUL
C29: 1. Gestion des Risques de Catastrophe | G29: > augmentation des sinistrés et des sans abris, et manque des outils > Augmentation du nombre de vols et de l'insécurité, | M29: > > Insufisance de prise de responsabilité | S29: Vulnérabilité MOYENNE | V29: =IF(S29="---","",VLOOKUP(S29,$C$69:$D$72,2,FALSE)) -> 0.67
C30: 2. Santé | G30: > Contamination de l’eau potable par les eaux de ruissellement, entraînant des maladies et se propager rapide ; Augmentatios des personnes malades , Propagation rapide des maladies : gale , diarrhée , paludisme , | M30: > Déversement de selles et de déchets , La durabilité de l'eau restante dans la communauté , Eau polluée , des puits polluée , Débordement des fosses septiques ( latrines), aggravant les risques sanitaires | S30: Vulnérabilité ELEVEE | V30: =IF(S30="---","",VLOOKUP(S30,$C$69:$D$72,2,FALSE)) -> 1
C31: 3. Eau et assainissement | G31: >Les eaux stagnantes favorisent la prolifération de moustiques (paludisme, dengue) et la contamination des sources d'eau potable.Pollution de puits , Saleté et transformation de qualité d'eau , Eau polluée , des puits polluée , Contamination de l’eau potable par les eaux de ruissellement, | M31: > Pas assez d'eau potable et BF > Eau polluée et salé > montée de l'eau notament la marré haute d'EQUINOX > Défécation à l'air libre , manque d'habitude sur le traitement de l'eau et de lavage des mains . | S31: Vulnérabilité MOYENNE | V31: =IF(S31="---","",VLOOKUP(S31,$C$69:$D$72,2,FALSE)) -> 0.67
C32: 4.Logement | G32: > Dégradation des matériaux de construction (murs, fondations, toitures) due à l'eau. >Maisons détruites ou menacées , effondrement total ou partiel des habitations. >Accumulation de boue, détritus ou saletés à l'intérieur des habitations.Les logements en matériaux non résistants (terre battue) sont souvent emportés. | M32: > Manque d’alternatives pour les populations à faible revenu. Utilisation de matériaux non résistants à l'eau, comme le bois non traité, la terre battue, ou les briques non stabilisées ; Absence de surélévation par rapport au niveau du sol, ce qui expose directement le logement aux inondations. Mauvaise conception des fondations, entraînant des effondrements ou des infiltrations. | S32: Vulnérabilité MOYENNE | V32: =IF(S32="---","",VLOOKUP(S32,$C$69:$D$72,2,FALSE)) -> 0.67
C33: 5. Alimentation et nutrition | G33: > les stocks se pourissent , hausse de prix de nourriture , Insuffisance alimentaire ; augmentation d'insécurité alimentaire | M33: > Pas assez de nourriture à épargnés ; Les familles perdent leurs terres agricoles, aggravant l'insuffisance alimentaire , la pauvreté ; Consommation de nourriture non saine , insuffisante | S33: Vulnérabilité ELEVEE | V33: =IF(S33="---","",VLOOKUP(S33,$C$69:$D$72,2,FALSE)) -> 1
C34: 6. Opportunités économiques | G34: > La mort des animaux ; Détérioration de la qualité de vie et difficulté à se relever après l'inondation > Dimunition de source de revenu ; Les familles doivent consacrer leurs économies ou s'endetter pour réparer ou reconstruire leurs logements ; Certain perdent leurs terres agricoles, aggravant la pauvreté. > Augmentation de la pauvreté | M34: > Cessation des activités commercial > Eaux polluées > Les produits pourrissent > Baisse de la clientèle > Marchés inondés > dificulté de déplacement pour travailler | S34: Vulnérabilité MOYENNE | V34: =IF(S34="---","",VLOOKUP(S34,$C$69:$D$72,2,FALSE)) -> 0.67
C35: 7. Infrastructure et services | G35: > Fermeture des services , des écoles et de prestation ; Les administrations locales ne peuvent fonctionner normalement, ce qui retarde la gestion des crises et les services à la population ; Déstructions et fissuration des 'infrastructures ; L’accueil prolongé des sinistrés retarde la reprise des cours, perturbant l’année scolaire des élèves.Les canaux bouchés empêchent l'évacuation rapide des eaux pluviales, entraînant des inondations prolongées. | M35: > Chemins non pavés rendus impraticables par la boue ; Déversement des déchets partout dans la communautés ; Bâtiments endommagés ou détruits, interrompant les activités éducatives et administratives ; Utilisation des écoles comme abris temporaires, rendant leur réouverture difficile. | S35: Vulnérabilité MOYENNE | V35: =IF(S35="---","",VLOOKUP(S35,$C$69:$D$72,2,FALSE)) -> 0.67
C36: 8. Gestion des ressources naturelles | G36: > Pollution accrue des zones naturelles et dans la mer ; Les débris des logements détruits et les matériaux polluants se dispersent dans la nature | M36: > Défecation dans la nature > Dépôt d'ordure dans les zones naturelles et sur les zones côtières ;La croissance urbaine incontrôlée dans les zones à haut risque augmente la vulnérabilité des populations et des ressources naturelles aux cyclones > Depôt d'ordure dans les zones naturelles et sur les zones côtières | S36: Vulnérabilité MOYENNE | V36: =IF(S36="---","",VLOOKUP(S36,$C$69:$D$72,2,FALSE)) -> 0.67
C37: 6. Social cohesion & Inclusion | G37: =#REF! -> #REF! | M37: =#REF! -> #REF! | S37: =#REF! -> #REF! | V37: =IF(S37="---","",VLOOKUP(S37,$C$69:$D$72,2,FALSE)) -> #REF!
C38: 7. Connectedness | G38: =#REF! -> #REF! | M38: =#REF! -> #REF! | S38: =#REF! -> #REF! | V38: =IF(S38="---","",VLOOKUP(S38,$C$69:$D$72,2,FALSE)) -> #REF!
C40: ='3. Dangers'!M16 -> Cyclone
C42: Ampleur | G42: Impact (passé et futur) | M42: Aspects de vulnérabilité avec leurs causes (la raison pour laquelle l'impact se produit et les causes profondes) | S42: Cote de vulnérabilité (choisissez dans la liste) | V42: Valeur de VUL
C43: 1. Gestion des Risques de Catastrophe | G43: >Dégat materiel et humains , augmentation des sinistrés et des sans abris, et manque des outils > Montée des déchets rejetées par la mer ; Les cyclones détruisent les cultures, les bétails et les commerces, rendant les communautés plus dépendantes des aides > Inondation ,montée des déchets et des selles | M43: > Toitures légères, matériaux de construction non résistants, absence de normes parasismiques ou anti-cycloniques à cause de la pauvreté empêchant l’investissement dans des matériaux robustes > Montée du niveau de la mer ; > Habitations situées dans des zones inondables ou des pentes instables. | S43: Vulnérabilité ELEVEE | V43: =IF(S43="---","",VLOOKUP(S43,$C$69:$D$72,2,FALSE)) -> 1
C44: 2. Santé | G44: > Diarrhée, Paludisme , Contamination de l’eau potable par les eaux de ruissellement, entraînant des maladies et se propager rapide comme le choléra, les diarrhées , la gale. >Prolifération des moustiques dans les zones inondées, augmentant les cas de paludisme et de dengue. Surcharge des services de santé due à l'augmentation des maladies post-inondation ; Incapacité des hôpitaux à fournir des soins adéquats | M44: > Dépot de déchets et de l'eau presque permanent ; Déversement de selles et de déchets ; Débordement des fosses septiques ( latrines), aggravant les risques sanitaires ; | S44: Vulnérabilité ELEVEE | V44: =IF(S44="---","",VLOOKUP(S44,$C$69:$D$72,2,FALSE)) -> 1
C45: 3. Eau et assainissement | G45: > Contamination de l’eau potable par les eaux de ruissellement, Manque d'accés à l'eau potable , Les eaux stagnantes favorisent la prolifération de moustiques (paludisme, dengue) et la contamination des sources d'eau potable | M45: > Insuffisance des Borne Fontaine ,WC ; Insuffisance des Borne Fontaine ,WC > Défécation dans la nature , manque d'habitude sur le traitement de l'eau et de lavage de mains . >Déversement de selles et de déchets dans le puits et eau , Débordement des fosses septiques (latrines ), aggravant les risques de pollution d'eau et de la communauté | S45: Vulnérabilité ELEVEE | V45: =IF(S45="---","",VLOOKUP(S45,$C$69:$D$72,2,FALSE)) -> 1
C46: 4.Logement | G46: > Destruction des maisons > Dégradation des matériaux de construction (murs, fondations, toitures) due à l'eau. Accumulation de boue, détritus ou saletés à l'intérieur des habitations. > Cambriolage , inondation, fichuration des murs | M46: >Mauvaise conception des fondations, entraînant des effondrements ou des infiltrations. >Utilisation de matériaux non résistants à l'eau, comme le bois non traité, la terre battue, ou les briques non stabilisées. > Manque d’alternatives pour les populations à faible revenu. >Absence de surélévation par rapport au niveau du sol, ce qui expose directement le logement aux inondations. > Montée du niveau de la mer , et déborde au communautés | S46: Vulnérabilité ELEVEE | V46: =IF(S46="---","",VLOOKUP(S46,$C$69:$D$72,2,FALSE)) -> 1
C47: 5. Alimentation et nutrition | G47: > Insuffisance alimentaire ; Malnutrition , augmentation de l'insécurité alimentaire , hausse de prix des nourritures | M47: >La perte de terres agricoles et érosion des sols qui dégradent les sols agricoles, ce qui rend les terres moins productives et augmente l'insécurité alimentaire. Insufisance de stockage de nourriture , Les familles perdent leurs terres agricoles, aggravant l'insuffisance alimentaire , la pauvreté . | S47: Vulnérabilité MOYENNE | V47: =IF(S47="---","",VLOOKUP(S47,$C$69:$D$72,2,FALSE)) -> 0.67
C48: 6. Opportunités économiques | G48: > Les familles doivent consacrer leurs économies ou s'endetter pour réparer ou reconstruire leurs logements.Certain perdent leurs terres agricoles, aggravant la pauvreté. Détérioration de la qualité de vie et difficulté à se relever après l'inondation > Difficultés financières et fragilisation des ménages > Les terres agricoles et les ressources naturelles (pêche, forêts) sont souvent endommagées, réduisant la productivité économique. > Les habitants perdent leurs moyens de subsistance, notamment pour ceux qui travaillent depuis leur domicile ou dans l'agriculture > Hausse généralisée des prix la mort des animaux | M48: > Impossibilité d'aller pêcher car la mer est trop agitée > Coupure des routes > Perte d'emploi > Animaux d'élevage emportés par l'eau | S48: Vulnérabilité ELEVEE | V48: =IF(S48="---","",VLOOKUP(S48,$C$69:$D$72,2,FALSE)) -> 1
C49: 7. Infrastructure et services | G49: > Concentration des sinistrés à un seul endroit - propogation encore plus rapide des maladies, bousculades > Enfants ne peuvent pas aller à l'école > Les gens ne peuvent pas se déplacer ; | M49: > Déracinement de la borne à fontaine > Canaux bouchés et remplis d'ordures , Bâtiments endommagés ou détruits, interrompant les activités éducatives et administratives. >Utilisation des écoles comme abris temporaires, rendant leur réouverture difficile. >Chemins non pavés rendus impraticables par la boue > Manque de bac à ordure , manque de Bloc sanitaire | S49: Vulnérabilité ELEVEE | V49: =IF(S49="---","",VLOOKUP(S49,$C$69:$D$72,2,FALSE)) -> 1
C50: 8. Gestion des ressources naturelles | G50: > Les cyclones peuvent entraîner de graves inondations, ce qui a un double impact sur les ressources en eau ; Instabilité de la mer , dégradation de l'environnement ;La perte de végétation peut entraîner une érosion des sols, un appauvrissement des terres et un impact négatif sur les espèces animales. | M50: > Perte de terres agricoles et érosion des sols ; La croissance urbaine incontrôlée dans les zones à haut risque augmente la vulnérabilité des populations et des ressources naturelles aux cyclones ; La destruction de forêts, de mangroves , qui sont des boucliers naturels contre l'érosion et les vagues de tempête. | S50: Vulnérabilité ELEVEE | V50: =IF(S50="---","",VLOOKUP(S50,$C$69:$D$72,2,FALSE)) -> 1
C51: 6. Social cohesion & Inclusion | G51: =G37 -> #REF! | M51: =M37 -> #REF! | S51: --- | V51: =IF(S51="---","",VLOOKUP(S51,$C$69:$D$72,2,FALSE))
C52: 7. Connectedness | G52: =G38 -> #REF! | M52: =M38 -> #REF! | S52: --- | V52: =IF(S52="---","",VLOOKUP(S52,$C$69:$D$72,2,FALSE))
C54: ='3. Dangers'!C32 -> Epidémies
C56: Ampleur | G56: Impact (passé et futur) | M56: Aspects de vulnérabilité avec leurs causes (la raison pour laquelle l'impact se produit et les causes profondes) | S56: Cote de vulnérabilité (choisissez dans la liste) | V56: Valeur de VUL
C57: 1. Gestion des Risques de Catastrophe | G57: >Les ressources humaines, financières et matérielles, normalement allouées à la gestion des risques de catastrophes, sont réorientées vers la lutte contre l’épidémie. >L’épidémie épuise les mécanismes de résilience des communautés, comme les réseaux de solidarité, les fonds d’épargne communautaires ou les capacités locales d’intervention . Les plans d'action pour des événements climatiques extrêmes, comme les cyclones, les inondations ou les sécheresses, sont souvent retardés ou compromis en raison de la priorité donnée à la gestion de l’épidémie Cela affaiblit la capacité de réponse à d'autres catastrophes | M57: >Perte de moyens de subsistance en raison des confinements et des restrictions, ce qui réduit la résilience économique des familles.Isolement social et restrictions qui empêchent la mobilisation communautaire ; Déversement des ordurs ,Saleté de la communauté | S57: Vulnérabilité ELEVEE | V57: =IF(S57="---","",VLOOKUP(S57,$C$69:$D$72,2,FALSE)) -> 1
C58: 2. Santé | G58: > Le maladie s'aggrave > Les épidémies augmentent significativement les cas de maladies et les décès dans la communauté. > Les gens doivent se tenir à distance les uns des autres > Automédication | M58: > Diminution de la qualité des soins pour tous les patients, y compris ceux atteints d'autres maladies. Mortalité accrue en raison de retards dans les soins ou du manque de ressources ; >Surcharge des établissements de santé, entraînant des délais de traitement ou l'absence de soins pour certaines maladies non liées à l'épidémie.Interruption des services de santé essentiels (vaccination, suivi des maladies chroniques, maternité). | S58: Vulnérabilité ELEVEE | V58: =IF(S58="---","",VLOOKUP(S58,$C$69:$D$72,2,FALSE)) -> 1
...

Sheet 5. Capacité
A1: Évaluation des Vulnérabilités et des Capacités Améliorée (EVCa) | Synthèse
A4: Informations générales
E5: ='1. Résumé'!E6 -> FKT 04/18_Tanambao | K5: ='1. Résumé'!G8 -> Pays : Madagascar
A8: 7. Capacité
C10: Quelles sont les forces disponibles pouvant être mobilisées et exploitée dans le but de réduire l'impact d'un danger ? Énumérez et décrivez les capacités (au niveau de la communauté, du ménage et de l'individu) qui existent pour faire face à chaque danger prioritaire en utilisant les caractéristiques clés de la résilience. Référez-vous aux directives EVCa à la page 40.
C12: Si nécessaire, ajoutez une brève analyse globale de la capacité ci-dessous.
C14: Volontariat local : Les jeunes et les membres de la communauté peuvent s’engager dans des initiatives d’entraide (construction de digues, distribution d’aide, etc.) , Solidarité communautaire : Les traditions malgaches, comme le fihavanana (esprit de solidarité), favorisent la coopération et le soutien mutuel en période de crise.
C16: ='3. Dangers'!C16 -> Inondation
C18: Ampleur | G18: Capacités (communauté, ménages, individus) | M18: Cote de capacité | P18: Valeur de CAP
C19: 1. Gestion des Risques de Catastrophe | G19: >Possession des nombreuse jeunes volontaires ; Existance d'Equipe Local de Sécours (ELS) , outils SAP ; Existance d'Organisation nationale de gestion des catastrophes (par exemple, le BNGRC) | M19: Capacité MOYENNE | P19: =IF(M19="---","",VLOOKUP(M19,$C$60:$D$63,2,FALSE)) -> 0.67
C20: 2. Santé | G20: >Agents communautaires , Communauté sensibilisée sur les gestes à suivre ce qui permet de faire diminuer la propagation des maladies | M20: Capacité MOYENNE | P20: =IF(M20="---","",VLOOKUP(M20,$C$60:$D$63,2,FALSE)) -> 0.67
C21: 3. Eau et assainissement | G21: > Borne Fontaine et Puits | M21: Capacité MOYENNE | P21: =IF(M21="---","",VLOOKUP(M21,$C$60:$D$63,2,FALSE)) -> 0.67
C22: 4.Logement | G22: >Possession des abris sécurisé ; Certains d'entre eux possedent de maison en dure , en parpaing , certains gens connaît les techniques traditionnelles pour renforcer les habitations contre les inondations en utilisant des ressources naturelles | M22: Capacité MOYENNE | P22: =IF(M22="---","",VLOOKUP(M22,$C$60:$D$63,2,FALSE)) -> 0.67
C23: 5. Alimentation et nutrition | G23: >stockage des nourriture vivriere comme: manioc,maîs ,patate douce | M23: AUCUNE capacité | P23: =IF(M23="---","",VLOOKUP(M23,$C$60:$D$63,2,FALSE)) -> 0
C24: 6. Opportunités économiques | G24: >Relance de la production agricole, notamment pour les cultures adaptées aux conditions post-cycloniques (riziculture, cultures vivrières) ; Augmentation de la pêche artisanale et des revenus pour les pêcheurs locaux ; Emplois temporaires dans la construction (routes, maisons, écoles).Gagner de l'argent à hotelerie et PPN , Les terres inondées peuvent être enrichies par les sédiments apportés par l'inondation , augmentant leur fertilité. | M24: Capacité MOYENNE | P24: =IF(M24="---","",VLOOKUP(M24,$C$60:$D$63,2,FALSE)) -> 0.67
C25: 7. Infrastructure et services | G25: >Existance des abris comme: EPP et CEG Ankisirasira, Eglise Anglikanina utilisés comme des hébergements et accueils temporaires Hébèrgement entre voisins | M25: Capacité FAIBLE | P25: =IF(M25="---","",VLOOKUP(M25,$C$60:$D$63,2,FALSE)) -> 0.33
C26: 8. Gestion des ressources naturelles | G26: >Foret des mangroves ; Initiatives communautaires pour planter des arbres résilients. | M26: Capacité FAIBLE | P26: =IF(M26="---","",VLOOKUP(M26,$C$60:$D$63,2,FALSE)) -> 0.33
C27: 6. Social cohesion & Inclusion | G27: =#REF! -> #REF! | M27: =#REF! -> #REF! | P27: =IF(M27="---","",VLOOKUP(M27,$C$60:$D$63,2,FALSE)) -> #REF!
C28: 7. Connectedness | G28: =#REF! -> #REF! | M28: =#REF! -> #REF! | P28: =IF(M28="---","",VLOOKUP(M28,$C$60:$D$63,2,FALSE)) -> #REF!
C30: ='3. Dangers'!M16 -> Cyclone
C32: Ampleur | G32: Capacités (communauté, ménages, individus) | M32: Cote de capacité | P32: Valeur de CAP
C33: 1. Gestion des Risques de Catastrophe | G33: >Existance des ELS ,outils SAP (Gillet de sauvetage , pirogue , bottes de pluis , Torche , mégaphone , sifflet ) ; Connaissance des comportements cycloniques et des refuges naturels sûrs ; Partage des informations par les agents communaitaires, alertes météo, alertes précoces , existance d'Organisation nationale de gestion des catastrophes ( le BNGRC) ; | M33: Capacité MOYENNE | P33: =IF(M33="---","",VLOOKUP(M33,$C$60:$D$63,2,FALSE)) -> 0.67
C34: 2. Santé | G34: >Agents communautaires fournir des sensibilisation et des conseils | M34: Capacité MOYENNE | P34: =IF(M34="---","",VLOOKUP(M34,$C$60:$D$63,2,FALSE)) -> 0.67
C35: 3. Eau et assainissement | G35: >Forage , BF | M35: Capacité MOYENNE | P35: =IF(M35="---","",VLOOKUP(M35,$C$60:$D$63,2,FALSE)) -> 0.67
C36: 4.Logement | G36: >Certains Maisons en dur / parpin et en bois ce qui permet de limiter les dégâts | M36: Capacité ELEVEE | P36: =IF(M36="---","",VLOOKUP(M36,$C$60:$D$63,2,FALSE)) -> 1
C37: 5. Alimentation et nutrition | G37: >Stockage de nourriture vivrière , Un peu de soutien mutuel pour l’hébergement temporaire ou le partage des aliments entre familles ; Stocks pré-positionnés de nourriture, d’eau potable, et de matériaux d’urgence | M37: Capacité MOYENNE | P37: =IF(M37="---","",VLOOKUP(M37,$C$60:$D$63,2,FALSE)) -> 0.67
C38: 6. Opportunités économiques | G38: >Vente des animaux ; Emplois temporaires dans la construction (routes, maisons, écoles) ; Les terres inondées peuvent être enrichies par les sédiments apportés par le cyclone, augmentant leur fertilité ; Augmentation de la pêche artisanale et des revenus pour les pêcheurs locaux ; gagner de l'argent à hotelerie et PPN ; | M38: Capacité MOYENNE | P38: =IF(M38="---","",VLOOKUP(M38,$C$60:$D$63,2,FALSE)) -> 0.67
C39: 7. Infrastructure et services | G39: >BF, Ecole , Eglise , terrain basket , accueils temporaires Hébèrgement entre voisins | M39: Capacité MOYENNE | P39: =IF(M39="---","",VLOOKUP(M39,$C$60:$D$63,2,FALSE)) -> 0.67
C40: 8. Gestion des ressources naturelles | G40: >Possession des foret de mangroves ; >Réboisement des jeunes plantes (mangroves) , Connaît les techniques traditionnelles pour renforcer les habitations contre les vents forts en utilisant des ressources naturelles ; | M40: Capacité FAIBLE | P40: =IF(M40="---","",VLOOKUP(M40,$C$60:$D$63,2,FALSE)) -> 0.33
C41: 6. Social cohesion & Inclusion | G41: =G27 -> #REF! | M41: =#REF! -> #REF! | P41: =IF(M41="---","",VLOOKUP(M41,$C$60:$D$63,2,FALSE)) -> #REF!
C42: 7. Connectedness | G42: =G28 -> #REF! | M42: =M28 -> #REF! | P42: =IF(M42="---","",VLOOKUP(M42,$C$60:$D$63,2,FALSE)) -> #REF!
C44: ='3. Dangers'!C32 -> Epidémies
C46: Ampleur | G46: Capacités (communauté, ménages, individus) | M46: Cote de capacité | P46: Valeur de CAP
C47: 1. Gestion des Risques de Catastrophe | G47: >Equipe Local de Secours (ELS) ; Elle sont beaucoup des volontaires formé par la CRM , Implication des chefs de villages, des associations de femmes et des groupes de jeunes pour diffuser les messages de prévention ; Agents communautaires pour la sensibilisation aux épidémies, prévention ; | M47: Capacité MOYENNE | P47: =IF(M47="---","",VLOOKUP(M47,$C$60:$D$63,2,FALSE)) -> 0.67
C48: 2. Santé | G48: >AC , Mégaphone 01 , Existence de aide soignante paramed pour une prise en charge des soins | M48: Capacité MOYENNE | P48: =IF(M48="---","",VLOOKUP(M48,$C$60:$D$63,2,FALSE)) -> 0.67
C49: 3. Eau et assainissement | G49: >BF , Japis , Puits | M49: Capacité MOYENNE | P49: =IF(M49="---","",VLOOKUP(M49,$C$60:$D$63,2,FALSE)) -> 0.67
C50: 4.Logement | G50: >Certains maisons est propre et il n'y a pas de risque de contamination en plus en dure/ parpaing | M50: Capacité FAIBLE | P50: =IF(M50="---","",VLOOKUP(M50,$C$60:$D$63,2,FALSE)) -> 0.33
C51: 5. Alimentation et nutrition | G51: >Stockage de nourriture vivrierre | M51: Capacité ELEVEE | P51: =IF(M51="---","",VLOOKUP(M51,$C$60:$D$63,2,FALSE)) -> 1
C52: 6. Opportunités économiques | G52: >Commerces et charpentis , collecte de produits aquatiques | M52: Capacité MOYENNE | P52: =IF(M52="---","",VLOOKUP(M52,$C$60:$D$63,2,FALSE)) -> 0.67
C53: 7. Infrastructure et services | G53: >Médecins privés , pas loin des hopitaux | M53: Capacité MOYENNE | P53: =IF(M53="---","",VLOOKUP(M53,$C$60:$D$63,2,FALSE)) -> 0.67
...

Sheet 6. Cohésion, Inclusion, Connect
A1: Évaluation des Vulnérabilités et des Capacités Améliorée (EVCa) | Synthèse
A4: Informations générales
E5: ='1. Résumé'!E6 -> FKT 04/18_Tanambao | K5: ='1. Résumé'!G8 -> Pays : Madagascar | R5: ='1. Résumé'!E10 -> Société nationale : Croix-Rouge Malagasy
A8: 5. Cote de RISQUE pour la cohésion sociale, l'inclusion et la connectivité
C10: Si nécessaire, ajoutez une brève analyse globale de ces dimensions de résilience ci-dessous.
C12: La cohesion sociale est une question dificile à poser, mais après discution entre les membres du fokontany, on sent de l'entraide en temps d'urgence dans le fokontany
C14: Cote de RISQUE pour la cohésion sociale, l'inclusion et la connectivité pour l'ensemble de la communauté
C15: Fournissez des détails à partir des diagrammes de Venn afin d’expliquer les classements.
C16: Cohésion sociale | G16: >Manque de cohesion sociaux pendant l'urgence catastrophique mais en cas de décès ; Conflits intercommunautaires ou tensions ethniques | S16: MOYENNE | T16: =IF(S16="---","",VLOOKUP(S16,$C$22:$D$25,2,FALSE)) -> 0.67
C17: Inclusion | G17: >Diversité ethnique, linguistique et religieuse pouvant influencer la cohésion sociale ; Discrimination , corruption , | S17: MOYENNE | T17: =IF(S17="---","",VLOOKUP(S17,$C$22:$D$25,2,FALSE)) -> 0.67
C18: Connectivité | G18: >Rétard de feedback de la demande , Les routes impraticables empêchent le transport de biens et services, perturbant les chaînes d’approvisionnement locales | S18: FAIBLE | T18: =IF(S18="---","",VLOOKUP(S18,$C$22:$D$25,2,FALSE)) -> 0.33
C22: ELEVEE | D22: 1
C23: MOYENNE | D23: 0.67
C24: FAIBLE | D24: 0.33

Sheet 7. Risque
A1: Évaluation des Vulnérabilités et des Capacités Améliorée (EVCa) | Synthèse
A4: Informations générales
E5: ='1. Résumé'!E6 -> FKT 04/18_Tanambao
A8: 8. Risque
C10: Les tableaux ci-dessous présentent un résumé des notes que vous avez fournies dans les feuilles précédentes. Sur cette base, les scores de risque ont été calculés et sont affichés à droite. Pour le risque global, référez-vous au bas de ce tableau.
C12: ='3. Dangers'!C16 -> Inondation
U13: Vulnerability
C14: Ampleur | H14: VUL (0.00 à 1.00) | J14: CAP (0.00 à 1.00) | M14: Cote de RISQUE | U14: No | V14: Low | W14: Moderate | X14: High
C15: 1. Gestion des Risques de Catastrophe | H15: ='4. Vulnérabilité'!V29 -> 0.67 | J15: ='5. Capacité'!P19 -> 0.67 | M15: =IF(AND(H15<>"",J15<>""),IF((H15-J15)<-0.32,"LOW",IF((H15-J15)<0.33,"MODERATE","HIGH")),"") -> MODERATE | S15: Capacity | U15: 0 | V15: 0.33 | W15: 0.67 | X15: 1
C16: 2. Santé | H16: ='4. Vulnérabilité'!V30 -> 1 | J16: ='5. Capacité'!P20 -> 0.67 | M16: =IF(AND(H16<>"",J16<>""),IF((H16-J16)<-0.33,"LOW",IF((H16-J16)<0.32,"MODERATE","HIGH")),"") -> HIGH | S16: High | T16: 1 | U16: LOW | V16: LOW | W16: LOW | X16: MODERATE
C17: 3. Eau et assainissement | H17: ='4. Vulnérabilité'!V31 -> 0.67 | J17: ='5. Capacité'!P21 -> 0.67 | M17: =IF(AND(H17<>"",J17<>""),IF((H17-J17)<-0.33,"LOW",IF((H17-J17)<0.32,"MODERATE","HIGH")),"") -> MODERATE
C18: 4.Logement | H18: ='4. Vulnérabilité'!V32 -> 0.67 | J18: ='5. Capacité'!P22 -> 0.67 | M18: =IF(AND(H18<>"",J18<>""),IF((H18-J18)<-0.33,"LOW",IF((H18-J18)<0.32,"MODERATE","HIGH")),"") -> MODERATE
C19: 5. Alimentation et nutrition | H19: ='4. Vulnérabilité'!V33 -> 1 | J19: ='5. Capacité'!P23 -> 0 | M19: =IF(AND(H19<>"",J19<>""),IF((H19-J19)<-0.33,"LOW",IF((H19-J19)<0.32,"MODERATE","HIGH")),"") -> HIGH
C20: 6. Opportunités économiques | H20: ='4. Vulnérabilité'!V34 -> 0.67 | J20: ='5. Capacité'!P24 -> 0.67 | M20: =IF(AND(H20<>"",J20<>""),IF((H20-J20)<-0.33,"LOW",IF((H20-J20)<0.32,"MODERATE","HIGH")),"") -> MODERATE | S20: Moderate | T20: 0.67 | U20: LOW | V20: LOW | W20: MODERATE | X20: HIGH
C21: 7. Infrastructure et services | H21: ='4. Vulnérabilité'!V35 -> 0.67 | J21: ='5. Capacité'!P25 -> 0.33 | M21: =IF(AND(H21<>"",J21<>""),IF((H21-J21)<-0.33,"LOW",IF((H21-J21)<0.32,"MODERATE","HIGH")),"") -> HIGH | S21: Low | T21: 0.33 | U21: LOW | V21: MODERATE | W21: HIGH | X21: HIGH
C22: 8. Gestion des ressources naturelles | H22: ='4. Vulnérabilité'!V36 -> 0.67 | J22: ='5. Capacité'!P26 -> 0.33 | M22: =IF(AND(H22<>"",J22<>""),IF((H22-J22)<-0.33,"LOW",IF((H22-J22)<0.32,"MODERATE","HIGH")),"") -> HIGH | S22: No | T22: 0 | U22: MODERATE | V22: HIGH | W22: HIGH | X22: HIGH
C23: 9. Cohésion sociale | H23: N/D | J23: N/D | M23: ='6. Cohésion, Inclusion, Connect'!S16 -> MOYENNE
C24: 10. Inclusion | H24: N/D | M24: ='6. Cohésion, Inclusion, Connect'!S17 -> MOYENNE
C25: 11. Connectivité | H25: N/D | J25: N/D | M25: ='6. Cohésion, Inclusion, Connect'!S18 -> FAIBLE
C27: ='3. Dangers'!M16 -> Cyclone | U27: No | V27: Low | W27: Moderate | X27: High
S28: Capacity | U28: 0 | V28: 0.33 | W28: 0.67 | X28: 1
C29: Ampleur | H29: VUL | J29: CAP | M29: Cote de RISQUE | S29: High | T29: 1 | U29: =U28-T29 -> -1 | V29: =V28-T29 -> -0.67 | W29: =W28-T29 -> -0.33 | X29: =X28-T29 -> 0
C30: 1. Gestion des Risques de Catastrophe | H30: ='4. Vulnérabilité'!V43 -> 1 | J30: ='5. Capacité'!P33 -> 0.67 | M30: =IF(AND(H30<>"",J30<>""),IF((H30-J30)<-0.32,"LOW",IF((H30-J30)<0.33,"MODERATE","HIGH")),"") -> HIGH | S30: Moderate | T30: 0.67 | U30: =U28-T30 -> -0.67 | V30: =V28-T30 -> -0.34 | W30: =W28-T30 -> 0 | X30: =X28-T30 -> 0.33
C31: 2. Santé | H31: ='4. Vulnérabilité'!V44 -> 1 | J31: ='5. Capacité'!P34 -> 0.67 | M31: =IF(AND(H31<>"",J31<>""),IF((H31-J31)<-0.32,"LOW",IF((H31-J31)<0.33,"MODERATE","HIGH")),"") -> HIGH | S31: Low | T31: 0.33 | U31: =U28-T31 -> -0.33 | V31: =V28-T31 -> 0 | W31: =W28-T31 -> 0.34 | X31: =X28-T31 -> 0.67
C32: 3. Eau et assainissement | H32: ='4. Vulnérabilité'!V45 -> 1 | J32: ='5. Capacité'!P35 -> 0.67 | M32: =IF(AND(H32<>"",J32<>""),IF((H32-J32)<-0.32,"LOW",IF((H32-J32)<0.33,"MODERATE","HIGH")),"") -> HIGH
C33: 4.Logement | H33: ='4. Vulnérabilité'!V46 -> 1 | J33: ='5. Capacité'!P36 -> 1 | M33: =IF(AND(H33<>"",J33<>""),IF((H33-J33)<-0.32,"LOW",IF((H33-J33)<0.33,"MODERATE","HIGH")),"") -> MODERATE
C34: 5. Alimentation et nutrition | H34: ='4. Vulnérabilité'!V47 -> 0.67 | J34: ='5. Capacité'!P37 -> 0.67 | M34: =IF(AND(H34<>"",J34<>""),IF((H34-J34)<-0.32,"LOW",IF((H34-J34)<0.33,"MODERATE","HIGH")),"") -> MODERATE
C35: 6. Opportunités économiques | H35: ='4. Vulnérabilité'!V48 -> 1 | J35: ='5. Capacité'!P38 -> 0.67 | M35: =IF(AND(H35<>"",J35<>""),IF((H35-J35)<-0.32,"LOW",IF((H35-J35)<0.33,"MODERATE","HIGH")),"") -> HIGH | S35: No | T35: 0 | U35: 0 | V35: =V28-T35 -> 0.33 | W35: =W28-T35 -> 0.67 | X35: =X28-T35 -> 1
C36: 7. Infrastructure et services | H36: ='4. Vulnérabilité'!V49 -> 1 | J36: ='5. Capacité'!P39 -> 0.67 | M36: =IF(AND(H36<>"",J36<>""),IF((H36-J36)<-0.32,"LOW",IF((H36-J36)<0.33,"MODERATE","HIGH")),"") -> HIGH
C37: 8. Gestion des ressources naturelles | H37: ='4. Vulnérabilité'!V50 -> 1 | J37: ='5. Capacité'!P40 -> 0.33 | M37: =IF(AND(H37<>"",J37<>""),IF((H37-J37)<-0.32,"LOW",IF((H37-J37)<0.33,"MODERATE","HIGH")),"") -> HIGH
C38: 9. Cohésion sociale | H38: N/D | J38: N/D | M38: =M23 -> MOYENNE
C39: 10. Inclusion | M39: =M24 -> MOYENNE
C40: 11. Connectivité | H40: N/D | J40: N/D | M40: =M25 -> FAIBLE
C42: ='3. Dangers'!C32 -> Epidémies
C44: Ampleur | H44: VUL | J44: CAP | M44: Cote de RISQUE
C45: 1. Gestion des Risques de Catastrophe | H45: ='4. Vulnérabilité'!V57 -> 1 | J45: ='5. Capacité'!P47 -> 0.67 | M45: =IF(AND(H45<>"",J45<>""),IF((H45-J45)<-0.32,"LOW",IF((H45-J45)<0.33,"MODERATE","HIGH")),"") -> HIGH
C46: 2. Santé | H46: ='4. Vulnérabilité'!V58 -> 1 | J46: ='5. Capacité'!P48 -> 0.67 | M46: =IF(AND(H46<>"",J46<>""),IF((H46-J46)<-0.32,"LOW",IF((H46-J46)<0.33,"MODERATE","HIGH")),"") -> HIGH
C47: 3. Eau et assainissement | H47: ='4. Vulnérabilité'!V59 -> 1 | J47: ='5. Capacité'!P49 -> 0.67 | M47: =IF(AND(H47<>"",J47<>""),IF((H47-J47)<-0.32,"LOW",IF((H47-J47)<0.33,"MODERATE","HIGH")),"") -> HIGH
C48: 4.Logement | H48: ='4. Vulnérabilité'!V60 -> 0.67 | J48: ='5. Capacité'!P50 -> 0.33 | M48: =IF(AND(H48<>"",J48<>""),IF((H48-J48)<-0.32,"LOW",IF((H48-J48)<0.33,"MODERATE","HIGH")),"") -> HIGH
C49: 5. Alimentation et nutrition | H49: ='4. Vulnérabilité'!V61 -> 1 | J49: ='5. Capacité'!P51 -> 1 | M49: =IF(AND(H49<>"",J49<>""),IF((H49-J49)<-0.32,"LOW",IF((H49-J49)<0.33,"MODERATE","HIGH")),"") -> MODERATE
...

Sheet 8. Analyse
A1: Évaluation des Vulnérabilités et des Capacités Améliorée (EVCa) | Synthèse
A4: Informations générales
E5: ='1. Résumé'!E6 -> FKT 04/18_Tanambao | J5: ='1. Résumé'!G8 -> Pays : Madagascar
A8: 2. Informations consolidées sur les risques - complétez cette section comme un résumé global à la fin du processus d'évaluation
C10: Pour chaque dimension identifiée comme présentant un risque élevé (et potentiellement moyen), regroupez les détails/informations relatifs à la vulnérabilité et à la capacité dans le tableau ci-dessous (c'est-à-dire copiez/collez les détails et informations relatifs à la vulnérabilité et à la capacité pour chaque dimension élevée (et potentiellement moyenne) des tableaux ci-dessus) . Référez-vous aux directives EVCa à la page 43.
C12: Danger | G12: Ampleur | J12: Éléments de vulnérabilité | L12: Éléments de capacité | N12: Résumé des risques clés
J13: Copiez le texte pertinent de la section 6 | L13: Copiez le texte pertinent de la section 7
C14: Inondation | G14: 7. Infrastructures et services | J14: >Bâtiments endommagés ou détruits, interrompant les activités éducatives et administratives.Utilisation des écoles comme abris temporaires, rendant leur réouverture difficile. Chemins non pavés rendus impraticables par la boue , déversement des déchets partout dans la communautés ; | L14: Existance des abris comme: EPP Tanambao , Centre de réfuge districal la voirie Morondava centre, utilisés comme des hébergements et accueils temporaires Hébèrgement entre voisins | N14: Perte de matériel éducatif comme les livres et les équipements ; Les routes inondées deviennent impraticables, interrompant les déplacements et le transport des marchandises ; Le canal d'évacuation mal entretenus entraînent une stagnation de l’eau . Les bâtiments résidentiels, commerciaux et publics peuvent être endommagés ou détruits.Le canal d'évacuation mal entretenus entraînent une stagnation de l’eau .
G15: 2. Santé | J15: > Débordement des fosses septiques ( latrines), aggravant les risques sanitaires ; Déversement de selles et de déchets ; La durabilité de l'eau restante dans la communauté , Eau polluée , des puits polluée , | L15: >Agents communautaires >Communauté sensibilisée sur les gestes à suivre ce qui permet de faire diminuer la propagation des maladies | N15: >Pollution accrue et risque de maladies dues aux déchets ; Centres de santé inondés ou endommagés, rendant l'accès aux soins difficile , Débordement des décharges ou des systèmes de collecte des ordures, répandant des déchets dans l’environnement ,
G16: 6. Opportunités économiques | J16: > Cessation des activités quotidiene > Eaux polluées > Les produits pourrissent > Baisse de la clientèle > Marchés inondés > Dificulté de déplacement pour travailler | L16: Relance de la production agricole, notamment pour les cultures adaptées aux conditions post-cycloniques (riziculture, cultures vivrières) ; Les terres inondées peuvent être enrichies par les sédiments apportés par l'inondation , augmentant leur fertilité ; Emplois temporaires dans la construction (routes, maisons, écoles) ; Augmentation de la pêche artisanale et des revenus pour les pêcheurs locaux ; | N16: 1. Perte d'investissements Les investisseurs hésitent à investir dans des zones sujettes aux inondations, réduisant les opportunités de croissance économique. Les infrastructures endommagées (routes, ponts, réseaux électriques) rendent les zones moins attractives pour les investissements futurs 2. Chômage temporaire ou prolongé Les entreprises fermées ou affectées par les inondations peuvent licencier ou suspendre leurs employés. Les secteurs informels, tels que les petits commerces de rue, sont particulièrement vulnérables. 3.Agriculture : Destruction des cultures, perte de bétail, et contamination des sols, réduisant les opportunités de revenus agricoles.
C17: Cyclone | G17: 3. Eau et assainissement | J17: > Les eaux stagnantes favorisent la prolifération de moustiques (paludisme, dengue) et la contamination des sources d'eau potable ; Eau polluée , des puits polluée , Contamination de l’eau potable par les eaux de ruissellement, Manque d'accés à l'eau potable , | L17: Traitement de l'eau faite par la communauté lors d'une passage d'inondation , mise en place de comités locaux pour superviser les activités d’eau et d’assainissement. Borne Fontaine (BF) et pompe be pour un accès à l'eau potable ce qui évite certaines maladies | N17: Rupture des infrastructures d'assainissement : Les systèmes d'assainissement (égouts, fosses septiques) peuvent être endommagés ou submergés, ce qui entraîne une mauvaise gestion des eaux usées. Cela peut causer la propagation de maladies liées à l'assainissement, telles que les infections cutanées et les maladies transmises par les selles ; Expose les populations à des risques sanitaire ; Contamination de l'eau potable : Les inondations causées par le cyclone peuvent contaminer les sources d'eau potable (puits, rivières, réservoirs), rendant l'eau impropre à la consommation. La présence de débris, de produits chimiques et de matières fécales peut augmenter le risque de maladies hydriques telles que la diarrhée, le choléra et d'autres infections gastro-intestinales. Rupture des infrastructures d'assainissement : Les systèmes d'assainissement (égouts, fosses septiques) peuvent être endommagés ou submergés, ce qui entraîne une mauvaise gestion des eaux usées. Cela peut causer la propagation de maladies liées à l'assainissement, telles que les infections cutanées et les maladies transmises par les selles.
G18: 4. Logement | J18: >Montée du niveau de la mer , et déborde au communautés ; > Manque d’alternatives pour les populations à faible revenu. >Utilisation de matériaux non résistants à l'eau, comme le bois non traité, la terre battue, ou les briques non stabilisées. > Absence de surélévation par rapport au niveau du sol, ce qui expose directement le logement aux inondations. > Mauvaise conception des fondations, entraînant des effondrements ou des infiltrations. | L18: Certains d'entre eux possedent de maison en dure , en parpaing , certains gens connaît les techniques traditionnelles pour renforcer les habitations contre le cyclone en utilisant des ressources naturelles ; Les efforts de renforcement des bâtiments, notamment les maisons, peuvent inclure la consolidation des structures, le renforcement des toitures et des fenêtres pour mieux résister aux conditions extrêmes. | N18: Les bâtiments mal conçus ou construits avec des matériaux faibles (comme des toits en tôle, des murs en briques non renforcées, etc.) sont vulnérables aux vents violents, à la pression de l'air et aux forces d'impact des débris soufflés. Cela peut entraîner l'effondrement partiel ou total des habitations. Impact : Des destructions massives de logements, des blessures et des pertes humaines.
G19: 7. Infrastructures et services | J19: >Utilisation des écoles comme abris temporaires, rendant leur réouverture difficile. > Canaux bouchés et remplis d'ordures , Bâtiments endommagés ou détruits, interrompant les activités éducatives et administratives. >Déracinement de la Borne à Fontaine | L19: BF, EPP ; Eglise Anglikanina utilisés comme des hébergements et accueils temporaires Hébèrgement entre voisins | N19: Interruption des services essentiels : Coupures d'électricité, d'eau potable, et de communication. Pénurie de biens essentiels (nourriture, médicaments). Crues soudaines et inondations dans les zones basses. Risque pour les personnes en raison des débris volants. Élévation rapide du niveau de la mer, causant des inondations côtières. Dommages aux bâtiments, infrastructures et habitations. Dégâts dans les communautés côtières.
C20: Epidémies | G20: 2. Santé | J20: >Surcharge des établissements de santé, entraînant des délais de traitement ou l'absence de soins pour certaines maladies non liées à l'épidémie.Interruption des services de santé essentiels (vaccination, suivi des maladies chroniques, maternité) ; Diminution de la qualité des soins pour tous les patients, y compris ceux atteints d'autres maladies. Mortalité accrue en raison de retards dans les soins ou du manque de ressources ; | L20: >Existence de aide soignante paramed pour une prise en charge médical , Réseaux de volontaires CRM locaux pour soutenir les efforts de secours. | N20: Diffusion de rumeurs ou de conseils médicaux erronés qui aggravent la situation et retardent les actions adéquates . -Ruptures de stock en médicaments, vaccins, matériel médical, et équipements de protection -Les soins pour d'autres pathologies (chroniques ou urgentes) sont retardés ou négligés.auto-médication , -Infections fréquentes chez les professionnels de santé, conduisant à un manque de personnel qualifié.-Absence de structures de santé adéquates pour répondre à la demande croissante.
A26: 2. Analyse des risques
C28: Résumez ci-dessous l’analyse globale.
